Workbook

Sheet PAINEL
E1: PAINEL DO MÊS
E2: Mês: | F2: JUNHO | G2: <- escolha aqui
E3: Meta 2 = Meta 1 x | F3: 1.12 | G3: Meta 3 = Meta 1 x | H3: 1.3
E4: Nada se digita nesta tela além do mês e dos dois fatores. Os números vêm da aba BASE.
E6: LOJA | F6: DIAS QUE FALTAM | G6: META 1 | H6: META 2 | I6: META 3 | J6: VENDA ATÉ HOJE | K6: % DA META 1 | L6: FALTA P/ META 1 | M6: VENDER POR DIA | N6: PROJEÇÃO DO MÊS | O6: SITUAÇÃO
E7: ITABORAÍ 2 - 257 | F7: =SUMIFS(BASE!$I$7:$I$126,BASE!$G$7:$G$126,$F$2,BASE!$H$7:$H$126,$E7)-SUMIFS(BASE!$J$7:$J$126,BASE!$G$7:$G$126,$F$2,BASE!$H$7:$H$126,$E7) -> 26 | G7: 159125 | H7: =$G7*$F$3 -> 178220 | I7: =$G7*$H$3 -> 206862.5 | J7: =SUMIFS(BASE!$L$7:$L$126,BASE!$G$7:$G$126,$F$2,BASE!$H$7:$H$126,$E7) -> 0 | K7: =IFERROR($J7/$G7,"") -> 0 | L7: =IF($G7=0,"",$G7-$J7) -> 159125 | M7: =IFERROR(IF($L7<=0,0,$L7/$F7),"") -> 6120.1923 | N7: =IFERROR($J7/SUMIFS(BASE!$J$7:$J$126,BASE!$G$7:$G$126,$F$2,BASE!$H$7:$H$126,$E7)*SUMIFS(BASE!$I$7:$I$126,BASE!$G$7:$G$126,$F$2,BASE!$H$7:$H$126,$E7),"") | O7: =IF($K7="","",IF($K7>=1,"BATEU",IF($K7>=0.85,"ATENÇÃO","CRÍTICO"))) -> CRÍTICO
E8: SÃO GONÇALO - 364 | F8: =SUMIFS(BASE!$I$7:$I$126,BASE!$G$7:$G$126,$F$2,BASE!$H$7:$H$126,$E8)-SUMIFS(BASE!$J$7:$J$126,BASE!$G$7:$G$126,$F$2,BASE!$H$7:$H$126,$E8) -> 26 | H8: =$G8*$F$3 -> 0 | I8: =$G8*$H$3 -> 0 | J8: =SUMIFS(BASE!$L$7:$L$126,BASE!$G$7:$G$126,$F$2,BASE!$H$7:$H$126,$E8) -> 0 | K8: =IFERROR($J8/$G8,"") | L8: =IF($G8=0,"",$G8-$J8) | M8: =IFERROR(IF($L8<=0,0,$L8/$F8),"") | N8: =IFERROR($J8/SUMIFS(BASE!$J$7:$J$126,BASE!$G$7:$G$126,$F$2,BASE!$H$7:$H$126,$E8)*SUMIFS(BASE!$I$7:$I$126,BASE!$G$7:$G$126,$F$2,BASE!$H$7:$H$126,$E8),"") | O8: =IF($K8="","",IF($K8>=1,"BATEU",IF($K8>=0.85,"ATENÇÃO","CRÍTICO")))
E9: CENTER 4 - 117 | F9: =SUMIFS(BASE!$I$7:$I$126,BASE!$G$7:$G$126,$F$2,BASE!$H$7:$H$126,$E9)-SUMIFS(BASE!$J$7:$J$126,BASE!$G$7:$G$126,$F$2,BASE!$H$7:$H$126,$E9) -> 26 | H9: =$G9*$F$3 -> 0 | I9: =$G9*$H$3 -> 0 | J9: =SUMIFS(BASE!$L$7:$L$126,BASE!$G$7:$G$126,$F$2,BASE!$H$7:$H$126,$E9) -> 0 | K9: =IFERROR($J9/$G9,"") | L9: =IF($G9=0,"",$G9-$J9) | M9: =IFERROR(IF($L9<=0,0,$L9/$F9),"") | N9: =IFERROR($J9/SUMIFS(BASE!$J$7:$J$126,BASE!$G$7:$G$126,$F$2,BASE!$H$7:$H$126,$E9)*SUMIFS(BASE!$I$7:$I$126,BASE!$G$7:$G$126,$F$2,BASE!$H$7:$H$126,$E9),"") | O9: =IF($K9="","",IF($K9>=1,"BATEU",IF($K9>=0.85,"ATENÇÃO","CRÍTICO")))
E10: CONCEIÇÃO - 109 | F10: =SUMIFS(BASE!$I$7:$I$126,BASE!$G$7:$G$126,$F$2,BASE!$H$7:$H$126,$E10)-SUMIFS(BASE!$J$7:$J$126,BASE!$G$7:$G$126,$F$2,BASE!$H$7:$H$126,$E10) -> 26 | H10: =$G10*$F$3 -> 0 | I10: =$G10*$H$3 -> 0 | J10: =SUMIFS(BASE!$L$7:$L$126,BASE!$G$7:$G$126,$F$2,BASE!$H$7:$H$126,$E10) -> 0 | K10: =IFERROR($J10/$G10,"") | L10: =IF($G10=0,"",$G10-$J10) | M10: =IFERROR(IF($L10<=0,0,$L10/$F10),"") | N10: =IFERROR($J10/SUMIFS(BASE!$J$7:$J$126,BASE!$G$7:$G$126,$F$2,BASE!$H$7:$H$126,$E10)*SUMIFS(BASE!$I$7:$I$126,BASE!$G$7:$G$126,$F$2,BASE!$H$7:$H$126,$E10),"") | O10: =IF($K10="","",IF($K10>=1,"BATEU",IF($K10>=0.85,"ATENÇÃO","CRÍTICO")))
E11: RIO BRANCO - 363 | F11: =SUMIFS(BASE!$I$7:$I$126,BASE!$G$7:$G$126,$F$2,BASE!$H$7:$H$126,$E11)-SUMIFS(BASE!$J$7:$J$126,BASE!$G$7:$G$126,$F$2,BASE!$H$7:$H$126,$E11) -> 26 | H11: =$G11*$F$3 -> 0 | I11: =$G11*$H$3 -> 0 | J11: =SUMIFS(BASE!$L$7:$L$126,BASE!$G$7:$G$126,$F$2,BASE!$H$7:$H$126,$E11) -> 0 | K11: =IFERROR($J11/$G11,"") | L11: =IF($G11=0,"",$G11-$J11) | M11: =IFERROR(IF($L11<=0,0,$L11/$F11),"") | N11: =IFERROR($J11/SUMIFS(BASE!$J$7:$J$126,BASE!$G$7:$G$126,$F$2,BASE!$H$7:$H$126,$E11)*SUMIFS(BASE!$I$7:$I$126,BASE!$G$7:$G$126,$F$2,BASE!$H$7:$H$126,$E11),"") | O11: =IF($K11="","",IF($K11>=1,"BATEU",IF($K11>=0.85,"ATENÇÃO","CRÍTICO")))
E12: SÃO JOSÉ - 236 | F12: =SUMIFS(BASE!$I$7:$I$126,BASE!$G$7:$G$126,$F$2,BASE!$H$7:$H$126,$E12)-SUMIFS(BASE!$J$7:$J$126,BASE!$G$7:$G$126,$F$2,BASE!$H$7:$H$126,$E12) -> 26 | H12: =$G12*$F$3 -> 0 | I12: =$G12*$H$3 -> 0 | J12: =SUMIFS(BASE!$L$7:$L$126,BASE!$G$7:$G$126,$F$2,BASE!$H$7:$H$126,$E12) -> 0 | K12: =IFERROR($J12/$G12,"") | L12: =IF($G12=0,"",$G12-$J12) | M12: =IFERROR(IF($L12<=0,0,$L12/$F12),"") | N12: =IFERROR($J12/SUMIFS(BASE!$J$7:$J$126,BASE!$G$7:$G$126,$F$2,BASE!$H$7:$H$126,$E12)*SUMIFS(BASE!$I$7:$I$126,BASE!$G$7:$G$126,$F$2,BASE!$H$7:$H$126,$E12),"") | O12: =IF($K12="","",IF($K12>=1,"BATEU",IF($K12>=0.85,"ATENÇÃO","CRÍTICO")))
E13: COPA 2 - 165 | F13: =SUMIFS(BASE!$I$7:$I$126,BASE!$G$7:$G$126,$F$2,BASE!$H$7:$H$126,$E13)-SUMIFS(BASE!$J$7:$J$126,BASE!$G$7:$G$126,$F$2,BASE!$H$7:$H$126,$E13) -> 26 | H13: =$G13*$F$3 -> 0 | I13: =$G13*$H$3 -> 0 | J13: =SUMIFS(BASE!$L$7:$L$126,BASE!$G$7:$G$126,$F$2,BASE!$H$7:$H$126,$E13) -> 0 | K13: =IFERROR($J13/$G13,"") | L13: =IF($G13=0,"",$G13-$J13) | M13: =IFERROR(IF($L13<=0,0,$L13/$F13),"") | N13: =IFERROR($J13/SUMIFS(BASE!$J$7:$J$126,BASE!$G$7:$G$126,$F$2,BASE!$H$7:$H$126,$E13)*SUMIFS(BASE!$I$7:$I$126,BASE!$G$7:$G$126,$F$2,BASE!$H$7:$H$126,$E13),"") | O13: =IF($K13="","",IF($K13>=1,"BATEU",IF($K13>=0.85,"ATENÇÃO","CRÍTICO")))
E14: TIJUCA 3 - 157 | F14: =SUMIFS(BASE!$I$7:$I$126,BASE!$G$7:$G$126,$F$2,BASE!$H$7:$H$126,$E14)-SUMIFS(BASE!$J$7:$J$126,BASE!$G$7:$G$126,$F$2,BASE!$H$7:$H$126,$E14) -> 26 | H14: =$G14*$F$3 -> 0 | I14: =$G14*$H$3 -> 0 | J14: =SUMIFS(BASE!$L$7:$L$126,BASE!$G$7:$G$126,$F$2,BASE!$H$7:$H$126,$E14) -> 0 | K14: =IFERROR($J14/$G14,"") | L14: =IF($G14=0,"",$G14-$J14) | M14: =IFERROR(IF($L14<=0,0,$L14/$F14),"") | N14: =IFERROR($J14/SUMIFS(BASE!$J$7:$J$126,BASE!$G$7:$G$126,$F$2,BASE!$H$7:$H$126,$E14)*SUMIFS(BASE!$I$7:$I$126,BASE!$G$7:$G$126,$F$2,BASE!$H$7:$H$126,$E14),"") | O14: =IF($K14="","",IF($K14>=1,"BATEU",IF($K14>=0.85,"ATENÇÃO","CRÍTICO")))
E15: RODRIGO SILVA - 997 | F15: =SUMIFS(BASE!$I$7:$I$126,BASE!$G$7:$G$126,$F$2,BASE!$H$7:$H$126,$E15)-SUMIFS(BASE!$J$7:$J$126,BASE!$G$7:$G$126,$F$2,BASE!$H$7:$H$126,$E15) -> 26 | H15: =$G15*$F$3 -> 0 | I15: =$G15*$H$3 -> 0 | J15: =SUMIFS(BASE!$L$7:$L$126,BASE!$G$7:$G$126,$F$2,BASE!$H$7:$H$126,$E15) -> 0 | K15: =IFERROR($J15/$G15,"") | L15: =IF($G15=0,"",$G15-$J15) | M15: =IFERROR(IF($L15<=0,0,$L15/$F15),"") | N15: =IFERROR($J15/SUMIFS(BASE!$J$7:$J$126,BASE!$G$7:$G$126,$F$2,BASE!$H$7:$H$126,$E15)*SUMIFS(BASE!$I$7:$I$126,BASE!$G$7:$G$126,$F$2,BASE!$H$7:$H$126,$E15),"") | O15: =IF($K15="","",IF($K15>=1,"BATEU",IF($K15>=0.85,"ATENÇÃO","CRÍTICO")))
E16: RODO 3 - 1017 | F16: =SUMIFS(BASE!$I$7:$I$126,BASE!$G$7:$G$126,$F$2,BASE!$H$7:$H$126,$E16)-SUMIFS(BASE!$J$7:$J$126,BASE!$G$7:$G$126,$F$2,BASE!$H$7:$H$126,$E16) -> 26 | G16: =SUMIFS(BASE!$K$7:$K$126,BASE!$G$7:$G$126,$F$2,BASE!$H$7:$H$126,$E16) -> 0 | H16: =$G16*$F$3 -> 0 | I16: =$G16*$H$3 -> 0 | J16: =SUMIFS(BASE!$L$7:$L$126,BASE!$G$7:$G$126,$F$2,BASE!$H$7:$H$126,$E16) -> 0 | K16: =IFERROR($J16/$G16,"") | L16: =IF($G16=0,"",$G16-$J16) | M16: =IFERROR(IF($L16<=0,0,$L16/$F16),"") | N16: =IFERROR($J16/SUMIFS(BASE!$J$7:$J$126,BASE!$G$7:$G$126,$F$2,BASE!$H$7:$H$126,$E16)*SUMIFS(BASE!$I$7:$I$126,BASE!$G$7:$G$126,$F$2,BASE!$H$7:$H$126,$E16),"") | O16: =IF($K16="","",IF($K16>=1,"BATEU",IF($K16>=0.85,"ATENÇÃO","CRÍTICO")))
E17: TOTAL | G17: =SUM(G7:G16) -> 159125 | H17: =SUM(H7:H16) -> 178220 | I17: =SUM(I7:I16) -> 206862.5 | J17: =SUM(J7:J16) -> 0 | K17: =IFERROR(J17/G17,"") -> 0 | L17: =SUM(L7:L16) -> 159125 | M17: =SUM(M7:M16) -> 6120.1923 | N17: =SUM(N7:N16) -> 0
E19: PROJEÇÃO DO MÊS = onde a loja fecha se mantiver o ritmo atual.

Sheet BASE
G1: BASE — todos os meses, uma linha por loja
G2: É a única aba onde se digita. Preencha as colunas amarelas. Nunca crie aba nova, nunca mude a ordem das linhas.
G4: REALIZADO: exporte do Microvix e cole na coluna F — não digite loja por loja.
G6: MÊS | H6: LOJA | I6: DIAS ÚTEIS DO MÊS | J6: DIAS JÁ TRABALHADOS | K6: META 1 | L6: REALIZADO
G7: JANEIRO | H7: ITABORAÍ 2 - 257 | I7: 26 | J7: 26 | K7: 104672 | L7: 115212.11
G8: JANEIRO | H8: SÃO GONÇALO - 364 | I8: 26 | J8: 26
G9: JANEIRO | H9: CENTER 4 - 117 | I9: 26 | J9: 26 | K9: 120000 | L9: 101425.86
G10: JANEIRO | H10: CONCEIÇÃO - 109 | I10: 26 | J10: 26 | K10: 101199 | L10: 87927.27
G11: JANEIRO | H11: RIO BRANCO - 363 | I11: 26 | J11: 26 | K11: 205272 | L11: 127540.82
G12: JANEIRO | H12: SÃO JOSÉ - 236 | I12: 26 | J12: 26 | K12: 110000 | L12: 80248.13
G13: JANEIRO | H13: COPA 2 - 165 | I13: 26 | J13: 26 | K13: 180000 | L13: 134077.7
G14: JANEIRO | H14: TIJUCA 3 - 157 | I14: 26 | J14: 26 | K14: 141778 | L14: 135322.99
G15: JANEIRO | H15: RODRIGO SILVA - 997 | I15: 26 | J15: 26 | K15: 120000 | L15: 101310.26
G16: JANEIRO | H16: RODO 3 - 1017 | I16: 26 | J16: 26 | K16: 140000 | L16: 152021.53
G17: FEVEREIRO | H17: ITABORAÍ 2 - 257 | I17: 26 | J17: 26 | K17: 123284 | L17: 84654.27
G18: FEVEREIRO | H18: SÃO GONÇALO - 364 | I18: 26 | J18: 26
G19: FEVEREIRO | H19: CENTER 4 - 117 | I19: 26 | J19: 26 | K19: 120000 | L19: 85034.68
G20: FEVEREIRO | H20: CONCEIÇÃO - 109 | I20: 26 | J20: 26 | K20: 110000 | L20: 61886.97
G21: FEVEREIRO | H21: RIO BRANCO - 363 | I21: 26 | J21: 26 | K21: 158000 | L21: 94696.8
G22: FEVEREIRO | H22: SÃO JOSÉ - 236 | I22: 26 | J22: 26 | K22: 105000 | L22: 58266.17
G23: FEVEREIRO | H23: COPA 2 - 165 | I23: 26 | J23: 26 | K23: 168000 | L23: 107305.48
G24: FEVEREIRO | H24: TIJUCA 3 - 157 | I24: 26 | J24: 26 | K24: 165000 | L24: 102918.8
G25: FEVEREIRO | H25: RODRIGO SILVA - 997 | I25: 26 | J25: 26 | K25: 145000 | L25: 88651.15
G26: FEVEREIRO | H26: RODO 3 - 1017 | I26: 26 | J26: 26 | K26: 147000 | L26: 108206.22
G27: MARÇO | H27: ITABORAÍ 2 - 257 | I27: 26 | J27: 26 | K27: 150000 | L27: 160893.47
G28: MARÇO | H28: SÃO GONÇALO - 364 | I28: 26 | J28: 26
G29: MARÇO | H29: CENTER 4 - 117 | I29: 26 | J29: 26 | K29: 130000 | L29: 135921.39
G30: MARÇO | H30: CONCEIÇÃO - 109 | I30: 26 | J30: 26 | K30: 103829 | L30: 111317.47
G31: MARÇO | H31: RIO BRANCO - 363 | I31: 26 | J31: 26 | K31: 155000 | L31: 211346.6
G32: MARÇO | H32: SÃO JOSÉ - 236 | I32: 26 | J32: 26 | K32: 91449 | L32: 127108.93
G33: MARÇO | H33: COPA 2 - 165 | I33: 26 | J33: 26 | K33: 180000 | L33: 191891.56
G34: MARÇO | H34: TIJUCA 3 - 157 | I34: 26 | J34: 26 | K34: 152920 | L34: 189167.41
G35: MARÇO | H35: RODRIGO SILVA - 997 | I35: 26 | J35: 26 | K35: 155000 | L35: 166004.89
G36: MARÇO | H36: RODO 3 - 1017 | I36: 26 | J36: 26 | K36: 167493 | L36: 210418.91
G37: ABRIL | H37: ITABORAÍ 2 - 257 | I37: 26 | J37: 26 | K37: 150000 | L37: 132007.35
G38: ABRIL | H38: SÃO GONÇALO - 364 | I38: 26 | J38: 26
G39: ABRIL | H39: CENTER 4 - 117 | I39: 26 | J39: 26 | K39: 124012 | L39: 127244.65
G40: ABRIL | H40: CONCEIÇÃO - 109 | I40: 26 | J40: 26 | K40: 120000 | L40: 104741.32
G41: ABRIL | H41: RIO BRANCO - 363 | I41: 26 | J41: 26 | K41: 180000 | L41: 141908.95
G42: ABRIL | H42: SÃO JOSÉ - 236 | I42: 26 | J42: 26 | K42: 115000 | L42: 92795.8
...

Sheet ANO
E1: ANO 2026 — atualiza sozinho a partir da BASE
E3: META 1 (R$)
E4: LOJA | F4: JAN | G4: FEV | H4: MAR | I4: ABR | J4: MAI | K4: JUN | L4: JUL | M4: AGO | N4: SET | O4: OUT | P4: NOV | Q4: DEZ | R4: ANO
E5: ITABORAÍ 2 - 257 | F5: =SUMIFS(BASE!$K$7:$K$126,BASE!$G$7:$G$126,"JANEIRO",BASE!$H$7:$H$126,$E5) -> 104672 | G5: =SUMIFS(BASE!$K$7:$K$126,BASE!$G$7:$G$126,"FEVEREIRO",BASE!$H$7:$H$126,$E5) -> 123284 | H5: =SUMIFS(BASE!$K$7:$K$126,BASE!$G$7:$G$126,"MARÇO",BASE!$H$7:$H$126,$E5) -> 150000 | I5: =SUMIFS(BASE!$K$7:$K$126,BASE!$G$7:$G$126,"ABRIL",BASE!$H$7:$H$126,$E5) -> 150000 | J5: =SUMIFS(BASE!$K$7:$K$126,BASE!$G$7:$G$126,"MAIO",BASE!$H$7:$H$126,$E5) -> 233744 | K5: =SUMIFS(BASE!$K$7:$K$126,BASE!$G$7:$G$126,"JUNHO",BASE!$H$7:$H$126,$E5) -> 0 | L5: =SUMIFS(BASE!$K$7:$K$126,BASE!$G$7:$G$126,"JULHO",BASE!$H$7:$H$126,$E5) -> 0 | M5: =SUMIFS(BASE!$K$7:$K$126,BASE!$G$7:$G$126,"AGOSTO",BASE!$H$7:$H$126,$E5) -> 0 | N5: =SUMIFS(BASE!$K$7:$K$126,BASE!$G$7:$G$126,"SETEMBRO",BASE!$H$7:$H$126,$E5) -> 0 | O5: =SUMIFS(BASE!$K$7:$K$126,BASE!$G$7:$G$126,"OUTUBRO",BASE!$H$7:$H$126,$E5) -> 0 | P5: =SUMIFS(BASE!$K$7:$K$126,BASE!$G$7:$G$126,"NOVEMBRO",BASE!$H$7:$H$126,$E5) -> 0 | Q5: =SUMIFS(BASE!$K$7:$K$126,BASE!$G$7:$G$126,"DEZEMBRO",BASE!$H$7:$H$126,$E5) -> 0 | R5: =SUM(F5:Q5) -> 761700
E6: SÃO GONÇALO - 364 | F6: =SUMIFS(BASE!$K$7:$K$126,BASE!$G$7:$G$126,"JANEIRO",BASE!$H$7:$H$126,$E6) -> 0 | G6: =SUMIFS(BASE!$K$7:$K$126,BASE!$G$7:$G$126,"FEVEREIRO",BASE!$H$7:$H$126,$E6) -> 0 | H6: =SUMIFS(BASE!$K$7:$K$126,BASE!$G$7:$G$126,"MARÇO",BASE!$H$7:$H$126,$E6) -> 0 | I6: =SUMIFS(BASE!$K$7:$K$126,BASE!$G$7:$G$126,"ABRIL",BASE!$H$7:$H$126,$E6) -> 0 | J6: =SUMIFS(BASE!$K$7:$K$126,BASE!$G$7:$G$126,"MAIO",BASE!$H$7:$H$126,$E6) -> 0 | K6: =SUMIFS(BASE!$K$7:$K$126,BASE!$G$7:$G$126,"JUNHO",BASE!$H$7:$H$126,$E6) -> 0 | L6: =SUMIFS(BASE!$K$7:$K$126,BASE!$G$7:$G$126,"JULHO",BASE!$H$7:$H$126,$E6) -> 0 | M6: =SUMIFS(BASE!$K$7:$K$126,BASE!$G$7:$G$126,"AGOSTO",BASE!$H$7:$H$126,$E6) -> 0 | N6: =SUMIFS(BASE!$K$7:$K$126,BASE!$G$7:$G$126,"SETEMBRO",BASE!$H$7:$H$126,$E6) -> 0 | O6: =SUMIFS(BASE!$K$7:$K$126,BASE!$G$7:$G$126,"OUTUBRO",BASE!$H$7:$H$126,$E6) -> 0 | P6: =SUMIFS(BASE!$K$7:$K$126,BASE!$G$7:$G$126,"NOVEMBRO",BASE!$H$7:$H$126,$E6) -> 0 | Q6: =SUMIFS(BASE!$K$7:$K$126,BASE!$G$7:$G$126,"DEZEMBRO",BASE!$H$7:$H$126,$E6) -> 0 | R6: =SUM(F6:Q6) -> 0
E7: CENTER 4 - 117 | F7: =SUMIFS(BASE!$K$7:$K$126,BASE!$G$7:$G$126,"JANEIRO",BASE!$H$7:$H$126,$E7) -> 120000 | G7: =SUMIFS(BASE!$K$7:$K$126,BASE!$G$7:$G$126,"FEVEREIRO",BASE!$H$7:$H$126,$E7) -> 120000 | H7: =SUMIFS(BASE!$K$7:$K$126,BASE!$G$7:$G$126,"MARÇO",BASE!$H$7:$H$126,$E7) -> 130000 | I7: =SUMIFS(BASE!$K$7:$K$126,BASE!$G$7:$G$126,"ABRIL",BASE!$H$7:$H$126,$E7) -> 124012 | J7: =SUMIFS(BASE!$K$7:$K$126,BASE!$G$7:$G$126,"MAIO",BASE!$H$7:$H$126,$E7) -> 167300 | K7: =SUMIFS(BASE!$K$7:$K$126,BASE!$G$7:$G$126,"JUNHO",BASE!$H$7:$H$126,$E7) -> 0 | L7: =SUMIFS(BASE!$K$7:$K$126,BASE!$G$7:$G$126,"JULHO",BASE!$H$7:$H$126,$E7) -> 0 | M7: =SUMIFS(BASE!$K$7:$K$126,BASE!$G$7:$G$126,"AGOSTO",BASE!$H$7:$H$126,$E7) -> 0 | N7: =SUMIFS(BASE!$K$7:$K$126,BASE!$G$7:$G$126,"SETEMBRO",BASE!$H$7:$H$126,$E7) -> 0 | O7: =SUMIFS(BASE!$K$7:$K$126,BASE!$G$7:$G$126,"OUTUBRO",BASE!$H$7:$H$126,$E7) -> 0 | P7: =SUMIFS(BASE!$K$7:$K$126,BASE!$G$7:$G$126,"NOVEMBRO",BASE!$H$7:$H$126,$E7) -> 0 | Q7: =SUMIFS(BASE!$K$7:$K$126,BASE!$G$7:$G$126,"DEZEMBRO",BASE!$H$7:$H$126,$E7) -> 0 | R7: =SUM(F7:Q7) -> 661312
E8: CONCEIÇÃO - 109 | F8: =SUMIFS(BASE!$K$7:$K$126,BASE!$G$7:$G$126,"JANEIRO",BASE!$H$7:$H$126,$E8) -> 101199 | G8: =SUMIFS(BASE!$K$7:$K$126,BASE!$G$7:$G$126,"FEVEREIRO",BASE!$H$7:$H$126,$E8) -> 110000 | H8: =SUMIFS(BASE!$K$7:$K$126,BASE!$G$7:$G$126,"MARÇO",BASE!$H$7:$H$126,$E8) -> 103829 | I8: =SUMIFS(BASE!$K$7:$K$126,BASE!$G$7:$G$126,"ABRIL",BASE!$H$7:$H$126,$E8) -> 120000 | J8: =SUMIFS(BASE!$K$7:$K$126,BASE!$G$7:$G$126,"MAIO",BASE!$H$7:$H$126,$E8) -> 169598 | K8: =SUMIFS(BASE!$K$7:$K$126,BASE!$G$7:$G$126,"JUNHO",BASE!$H$7:$H$126,$E8) -> 0 | L8: =SUMIFS(BASE!$K$7:$K$126,BASE!$G$7:$G$126,"JULHO",BASE!$H$7:$H$126,$E8) -> 0 | M8: =SUMIFS(BASE!$K$7:$K$126,BASE!$G$7:$G$126,"AGOSTO",BASE!$H$7:$H$126,$E8) -> 0 | N8: =SUMIFS(BASE!$K$7:$K$126,BASE!$G$7:$G$126,"SETEMBRO",BASE!$H$7:$H$126,$E8) -> 0 | O8: =SUMIFS(BASE!$K$7:$K$126,BASE!$G$7:$G$126,"OUTUBRO",BASE!$H$7:$H$126,$E8) -> 0 | P8: =SUMIFS(BASE!$K$7:$K$126,BASE!$G$7:$G$126,"NOVEMBRO",BASE!$H$7:$H$126,$E8) -> 0 | Q8: =SUMIFS(BASE!$K$7:$K$126,BASE!$G$7:$G$126,"DEZEMBRO",BASE!$H$7:$H$126,$E8) -> 0 | R8: =SUM(F8:Q8) -> 604626
E9: RIO BRANCO - 363 | F9: =SUMIFS(BASE!$K$7:$K$126,BASE!$G$7:$G$126,"JANEIRO",BASE!$H$7:$H$126,$E9) -> 205272 | G9: =SUMIFS(BASE!$K$7:$K$126,BASE!$G$7:$G$126,"FEVEREIRO",BASE!$H$7:$H$126,$E9) -> 158000 | H9: =SUMIFS(BASE!$K$7:$K$126,BASE!$G$7:$G$126,"MARÇO",BASE!$H$7:$H$126,$E9) -> 155000 | I9: =SUMIFS(BASE!$K$7:$K$126,BASE!$G$7:$G$126,"ABRIL",BASE!$H$7:$H$126,$E9) -> 180000 | J9: =SUMIFS(BASE!$K$7:$K$126,BASE!$G$7:$G$126,"MAIO",BASE!$H$7:$H$126,$E9) -> 220000 | K9: =SUMIFS(BASE!$K$7:$K$126,BASE!$G$7:$G$126,"JUNHO",BASE!$H$7:$H$126,$E9) -> 0 | L9: =SUMIFS(BASE!$K$7:$K$126,BASE!$G$7:$G$126,"JULHO",BASE!$H$7:$H$126,$E9) -> 0 | M9: =SUMIFS(BASE!$K$7:$K$126,BASE!$G$7:$G$126,"AGOSTO",BASE!$H$7:$H$126,$E9) -> 0 | N9: =SUMIFS(BASE!$K$7:$K$126,BASE!$G$7:$G$126,"SETEMBRO",BASE!$H$7:$H$126,$E9) -> 0 | O9: =SUMIFS(BASE!$K$7:$K$126,BASE!$G$7:$G$126,"OUTUBRO",BASE!$H$7:$H$126,$E9) -> 0 | P9: =SUMIFS(BASE!$K$7:$K$126,BASE!$G$7:$G$126,"NOVEMBRO",BASE!$H$7:$H$126,$E9) -> 0 | Q9: =SUMIFS(BASE!$K$7:$K$126,BASE!$G$7:$G$126,"DEZEMBRO",BASE!$H$7:$H$126,$E9) -> 0 | R9: =SUM(F9:Q9) -> 918272
E10: SÃO JOSÉ - 236 | F10: =SUMIFS(BASE!$K$7:$K$126,BASE!$G$7:$G$126,"JANEIRO",BASE!$H$7:$H$126,$E10) -> 110000 | G10: =SUMIFS(BASE!$K$7:$K$126,BASE!$G$7:$G$126,"FEVEREIRO",BASE!$H$7:$H$126,$E10) -> 105000 | H10: =SUMIFS(BASE!$K$7:$K$126,BASE!$G$7:$G$126,"MARÇO",BASE!$H$7:$H$126,$E10) -> 91449 | I10: =SUMIFS(BASE!$K$7:$K$126,BASE!$G$7:$G$126,"ABRIL",BASE!$H$7:$H$126,$E10) -> 115000 | J10: =SUMIFS(BASE!$K$7:$K$126,BASE!$G$7:$G$126,"MAIO",BASE!$H$7:$H$126,$E10) -> 152846 | K10: =SUMIFS(BASE!$K$7:$K$126,BASE!$G$7:$G$126,"JUNHO",BASE!$H$7:$H$126,$E10) -> 0 | L10: =SUMIFS(BASE!$K$7:$K$126,BASE!$G$7:$G$126,"JULHO",BASE!$H$7:$H$126,$E10) -> 0 | M10: =SUMIFS(BASE!$K$7:$K$126,BASE!$G$7:$G$126,"AGOSTO",BASE!$H$7:$H$126,$E10) -> 0 | N10: =SUMIFS(BASE!$K$7:$K$126,BASE!$G$7:$G$126,"SETEMBRO",BASE!$H$7:$H$126,$E10) -> 0 | O10: =SUMIFS(BASE!$K$7:$K$126,BASE!$G$7:$G$126,"OUTUBRO",BASE!$H$7:$H$126,$E10) -> 0 | P10: =SUMIFS(BASE!$K$7:$K$126,BASE!$G$7:$G$126,"NOVEMBRO",BASE!$H$7:$H$126,$E10) -> 0 | Q10: =SUMIFS(BASE!$K$7:$K$126,BASE!$G$7:$G$126,"DEZEMBRO",BASE!$H$7:$H$126,$E10) -> 0 | R10: =SUM(F10:Q10) -> 574295
E11: COPA 2 - 165 | F11: =SUMIFS(BASE!$K$7:$K$126,BASE!$G$7:$G$126,"JANEIRO",BASE!$H$7:$H$126,$E11) -> 180000 | G11: =SUMIFS(BASE!$K$7:$K$126,BASE!$G$7:$G$126,"FEVEREIRO",BASE!$H$7:$H$126,$E11) -> 168000 | H11: =SUMIFS(BASE!$K$7:$K$126,BASE!$G$7:$G$126,"MARÇO",BASE!$H$7:$H$126,$E11) -> 180000 | I11: =SUMIFS(BASE!$K$7:$K$126,BASE!$G$7:$G$126,"ABRIL",BASE!$H$7:$H$126,$E11) -> 174501 | J11: =SUMIFS(BASE!$K$7:$K$126,BASE!$G$7:$G$126,"MAIO",BASE!$H$7:$H$126,$E11) -> 200000 | K11: =SUMIFS(BASE!$K$7:$K$126,BASE!$G$7:$G$126,"JUNHO",BASE!$H$7:$H$126,$E11) -> 0 | L11: =SUMIFS(BASE!$K$7:$K$126,BASE!$G$7:$G$126,"JULHO",BASE!$H$7:$H$126,$E11) -> 0 | M11: =SUMIFS(BASE!$K$7:$K$126,BASE!$G$7:$G$126,"AGOSTO",BASE!$H$7:$H$126,$E11) -> 0 | N11: =SUMIFS(BASE!$K$7:$K$126,BASE!$G$7:$G$126,"SETEMBRO",BASE!$H$7:$H$126,$E11) -> 0 | O11: =SUMIFS(BASE!$K$7:$K$126,BASE!$G$7:$G$126,"OUTUBRO",BASE!$H$7:$H$126,$E11) -> 0 | P11: =SUMIFS(BASE!$K$7:$K$126,BASE!$G$7:$G$126,"NOVEMBRO",BASE!$H$7:$H$126,$E11) -> 0 | Q11: =SUMIFS(BASE!$K$7:$K$126,BASE!$G$7:$G$126,"DEZEMBRO",BASE!$H$7:$H$126,$E11) -> 0 | R11: =SUM(F11:Q11) -> 902501
E12: TIJUCA 3 - 157 | F12: =SUMIFS(BASE!$K$7:$K$126,BASE!$G$7:$G$126,"JANEIRO",BASE!$H$7:$H$126,$E12) -> 141778 | G12: =SUMIFS(BASE!$K$7:$K$126,BASE!$G$7:$G$126,"FEVEREIRO",BASE!$H$7:$H$126,$E12) -> 165000 | H12: =SUMIFS(BASE!$K$7:$K$126,BASE!$G$7:$G$126,"MARÇO",BASE!$H$7:$H$126,$E12) -> 152920 | I12: =SUMIFS(BASE!$K$7:$K$126,BASE!$G$7:$G$126,"ABRIL",BASE!$H$7:$H$126,$E12) -> 171029 | J12: =SUMIFS(BASE!$K$7:$K$126,BASE!$G$7:$G$126,"MAIO",BASE!$H$7:$H$126,$E12) -> 235633 | K12: =SUMIFS(BASE!$K$7:$K$126,BASE!$G$7:$G$126,"JUNHO",BASE!$H$7:$H$126,$E12) -> 0 | L12: =SUMIFS(BASE!$K$7:$K$126,BASE!$G$7:$G$126,"JULHO",BASE!$H$7:$H$126,$E12) -> 0 | M12: =SUMIFS(BASE!$K$7:$K$126,BASE!$G$7:$G$126,"AGOSTO",BASE!$H$7:$H$126,$E12) -> 0 | N12: =SUMIFS(BASE!$K$7:$K$126,BASE!$G$7:$G$126,"SETEMBRO",BASE!$H$7:$H$126,$E12) -> 0 | O12: =SUMIFS(BASE!$K$7:$K$126,BASE!$G$7:$G$126,"OUTUBRO",BASE!$H$7:$H$126,$E12) -> 0 | P12: =SUMIFS(BASE!$K$7:$K$126,BASE!$G$7:$G$126,"NOVEMBRO",BASE!$H$7:$H$126,$E12) -> 0 | Q12: =SUMIFS(BASE!$K$7:$K$126,BASE!$G$7:$G$126,"DEZEMBRO",BASE!$H$7:$H$126,$E12) -> 0 | R12: =SUM(F12:Q12) -> 866360
E13: RODRIGO SILVA - 997 | F13: =SUMIFS(BASE!$K$7:$K$126,BASE!$G$7:$G$126,"JANEIRO",BASE!$H$7:$H$126,$E13) -> 120000 | G13: =SUMIFS(BASE!$K$7:$K$126,BASE!$G$7:$G$126,"FEVEREIRO",BASE!$H$7:$H$126,$E13) -> 145000 | H13: =SUMIFS(BASE!$K$7:$K$126,BASE!$G$7:$G$126,"MARÇO",BASE!$H$7:$H$126,$E13) -> 155000 | I13: =SUMIFS(BASE!$K$7:$K$126,BASE!$G$7:$G$126,"ABRIL",BASE!$H$7:$H$126,$E13) -> 150000 | J13: =SUMIFS(BASE!$K$7:$K$126,BASE!$G$7:$G$126,"MAIO",BASE!$H$7:$H$126,$E13) -> 180000 | K13: =SUMIFS(BASE!$K$7:$K$126,BASE!$G$7:$G$126,"JUNHO",BASE!$H$7:$H$126,$E13) -> 0 | L13: =SUMIFS(BASE!$K$7:$K$126,BASE!$G$7:$G$126,"JULHO",BASE!$H$7:$H$126,$E13) -> 0 | M13: =SUMIFS(BASE!$K$7:$K$126,BASE!$G$7:$G$126,"AGOSTO",BASE!$H$7:$H$126,$E13) -> 0 | N13: =SUMIFS(BASE!$K$7:$K$126,BASE!$G$7:$G$126,"SETEMBRO",BASE!$H$7:$H$126,$E13) -> 0 | O13: =SUMIFS(BASE!$K$7:$K$126,BASE!$G$7:$G$126,"OUTUBRO",BASE!$H$7:$H$126,$E13) -> 0 | P13: =SUMIFS(BASE!$K$7:$K$126,BASE!$G$7:$G$126,"NOVEMBRO",BASE!$H$7:$H$126,$E13) -> 0 | Q13: =SUMIFS(BASE!$K$7:$K$126,BASE!$G$7:$G$126,"DEZEMBRO",BASE!$H$7:$H$126,$E13) -> 0 | R13: =SUM(F13:Q13) -> 750000
E14: RODO 3 - 1017 | F14: =SUMIFS(BASE!$K$7:$K$126,BASE!$G$7:$G$126,"JANEIRO",BASE!$H$7:$H$126,$E14) -> 140000 | G14: =SUMIFS(BASE!$K$7:$K$126,BASE!$G$7:$G$126,"FEVEREIRO",BASE!$H$7:$H$126,$E14) -> 147000 | H14: =SUMIFS(BASE!$K$7:$K$126,BASE!$G$7:$G$126,"MARÇO",BASE!$H$7:$H$126,$E14) -> 167493 | I14: =SUMIFS(BASE!$K$7:$K$126,BASE!$G$7:$G$126,"ABRIL",BASE!$H$7:$H$126,$E14) -> 178902 | J14: =SUMIFS(BASE!$K$7:$K$126,BASE!$G$7:$G$126,"MAIO",BASE!$H$7:$H$126,$E14) -> 269314 | K14: =SUMIFS(BASE!$K$7:$K$126,BASE!$G$7:$G$126,"JUNHO",BASE!$H$7:$H$126,$E14) -> 0 | L14: =SUMIFS(BASE!$K$7:$K$126,BASE!$G$7:$G$126,"JULHO",BASE!$H$7:$H$126,$E14) -> 0 | M14: =SUMIFS(BASE!$K$7:$K$126,BASE!$G$7:$G$126,"AGOSTO",BASE!$H$7:$H$126,$E14) -> 0 | N14: =SUMIFS(BASE!$K$7:$K$126,BASE!$G$7:$G$126,"SETEMBRO",BASE!$H$7:$H$126,$E14) -> 0 | O14: =SUMIFS(BASE!$K$7:$K$126,BASE!$G$7:$G$126,"OUTUBRO",BASE!$H$7:$H$126,$E14) -> 0 | P14: =SUMIFS(BASE!$K$7:$K$126,BASE!$G$7:$G$126,"NOVEMBRO",BASE!$H$7:$H$126,$E14) -> 0 | Q14: =SUMIFS(BASE!$K$7:$K$126,BASE!$G$7:$G$126,"DEZEMBRO",BASE!$H$7:$H$126,$E14) -> 0 | R14: =SUM(F14:Q14) -> 902709
E15: TOTAL | F15: =SUM(F5:F14) -> 1222921 | G15: =SUM(G5:G14) -> 1241284 | H15: =SUM(H5:H14) -> 1285691 | I15: =SUM(I5:I14) -> 1363444 | J15: =SUM(J5:J14) -> 1828435 | K15: =SUM(K5:K14) -> 0 | L15: =SUM(L5:L14) -> 0 | M15: =SUM(M5:M14) -> 0 | ... R15: =SUM(R5:R14) -> 6941775
E17: REALIZADO (R$)
E18: LOJA | F18: JAN | G18: FEV | H18: MAR | I18: ABR | J18: MAI | K18: JUN | L18: JUL | M18: AGO | N18: SET | O18: OUT | P18: NOV | Q18: DEZ | R18: ANO
E19: ITABORAÍ 2 - 257 | F19: =SUMIFS(BASE!$L$7:$L$126,BASE!$G$7:$G$126,"JANEIRO",BASE!$H$7:$H$126,$E19) -> 115212.11 | G19: =SUMIFS(BASE!$L$7:$L$126,BASE!$G$7:$G$126,"FEVEREIRO",BASE!$H$7:$H$126,$E19) -> 84654.27 | H19: =SUMIFS(BASE!$L$7:$L$126,BASE!$G$7:$G$126,"MARÇO",BASE!$H$7:$H$126,$E19) -> 160893.47 | I19: =SUMIFS(BASE!$L$7:$L$126,BASE!$G$7:$G$126,"ABRIL",BASE!$H$7:$H$126,$E19) -> 132007.35 | J19: =SUMIFS(BASE!$L$7:$L$126,BASE!$G$7:$G$126,"MAIO",BASE!$H$7:$H$126,$E19) -> 149548.5 | K19: =SUMIFS(BASE!$L$7:$L$126,BASE!$G$7:$G$126,"JUNHO",BASE!$H$7:$H$126,$E19) -> 0 | L19: =SUMIFS(BASE!$L$7:$L$126,BASE!$G$7:$G$126,"JULHO",BASE!$H$7:$H$126,$E19) -> 0 | M19: =SUMIFS(BASE!$L$7:$L$126,BASE!$G$7:$G$126,"AGOSTO",BASE!$H$7:$H$126,$E19) -> 0 | N19: =SUMIFS(BASE!$L$7:$L$126,BASE!$G$7:$G$126,"SETEMBRO",BASE!$H$7:$H$126,$E19) -> 0 | O19: =SUMIFS(BASE!$L$7:$L$126,BASE!$G$7:$G$126,"OUTUBRO",BASE!$H$7:$H$126,$E19) -> 0 | P19: =SUMIFS(BASE!$L$7:$L$126,BASE!$G$7:$G$126,"NOVEMBRO",BASE!$H$7:$H$126,$E19) -> 0 | Q19: =SUMIFS(BASE!$L$7:$L$126,BASE!$G$7:$G$126,"DEZEMBRO",BASE!$H$7:$H$126,$E19) -> 0 | R19: =SUM(F19:Q19) -> 642315.7
E20: SÃO GONÇALO - 364 | F20: =SUMIFS(BASE!$L$7:$L$126,BASE!$G$7:$G$126,"JANEIRO",BASE!$H$7:$H$126,$E20) -> 0 | G20: =SUMIFS(BASE!$L$7:$L$126,BASE!$G$7:$G$126,"FEVEREIRO",BASE!$H$7:$H$126,$E20) -> 0 | H20: =SUMIFS(BASE!$L$7:$L$126,BASE!$G$7:$G$126,"MARÇO",BASE!$H$7:$H$126,$E20) -> 0 | I20: =SUMIFS(BASE!$L$7:$L$126,BASE!$G$7:$G$126,"ABRIL",BASE!$H$7:$H$126,$E20) -> 0 | J20: =SUMIFS(BASE!$L$7:$L$126,BASE!$G$7:$G$126,"MAIO",BASE!$H$7:$H$126,$E20) -> 0 | K20: =SUMIFS(BASE!$L$7:$L$126,BASE!$G$7:$G$126,"JUNHO",BASE!$H$7:$H$126,$E20) -> 0 | L20: =SUMIFS(BASE!$L$7:$L$126,BASE!$G$7:$G$126,"JULHO",BASE!$H$7:$H$126,$E20) -> 0 | M20: =SUMIFS(BASE!$L$7:$L$126,BASE!$G$7:$G$126,"AGOSTO",BASE!$H$7:$H$126,$E20) -> 0 | N20: =SUMIFS(BASE!$L$7:$L$126,BASE!$G$7:$G$126,"SETEMBRO",BASE!$H$7:$H$126,$E20) -> 0 | O20: =SUMIFS(BASE!$L$7:$L$126,BASE!$G$7:$G$126,"OUTUBRO",BASE!$H$7:$H$126,$E20) -> 0 | P20: =SUMIFS(BASE!$L$7:$L$126,BASE!$G$7:$G$126,"NOVEMBRO",BASE!$H$7:$H$126,$E20) -> 0 | Q20: =SUMIFS(BASE!$L$7:$L$126,BASE!$G$7:$G$126,"DEZEMBRO",BASE!$H$7:$H$126,$E20) -> 0 | R20: =SUM(F20:Q20) -> 0
E21: CENTER 4 - 117 | F21: =SUMIFS(BASE!$L$7:$L$126,BASE!$G$7:$G$126,"JANEIRO",BASE!$H$7:$H$126,$E21) -> 101425.86 | G21: =SUMIFS(BASE!$L$7:$L$126,BASE!$G$7:$G$126,"FEVEREIRO",BASE!$H$7:$H$126,$E21) -> 85034.68 | H21: =SUMIFS(BASE!$L$7:$L$126,BASE!$G$7:$G$126,"MARÇO",BASE!$H$7:$H$126,$E21) -> 135921.39 | I21: =SUMIFS(BASE!$L$7:$L$126,BASE!$G$7:$G$126,"ABRIL",BASE!$H$7:$H$126,$E21) -> 127244.65 | J21: =SUMIFS(BASE!$L$7:$L$126,BASE!$G$7:$G$126,"MAIO",BASE!$H$7:$H$126,$E21) -> 95764.39 | K21: =SUMIFS(BASE!$L$7:$L$126,BASE!$G$7:$G$126,"JUNHO",BASE!$H$7:$H$126,$E21) -> 0 | L21: =SUMIFS(BASE!$L$7:$L$126,BASE!$G$7:$G$126,"JULHO",BASE!$H$7:$H$126,$E21) -> 0 | M21: =SUMIFS(BASE!$L$7:$L$126,BASE!$G$7:$G$126,"AGOSTO",BASE!$H$7:$H$126,$E21) -> 0 | N21: =SUMIFS(BASE!$L$7:$L$126,BASE!$G$7:$G$126,"SETEMBRO",BASE!$H$7:$H$126,$E21) -> 0 | O21: =SUMIFS(BASE!$L$7:$L$126,BASE!$G$7:$G$126,"OUTUBRO",BASE!$H$7:$H$126,$E21) -> 0 | P21: =SUMIFS(BASE!$L$7:$L$126,BASE!$G$7:$G$126,"NOVEMBRO",BASE!$H$7:$H$126,$E21) -> 0 | Q21: =SUMIFS(BASE!$L$7:$L$126,BASE!$G$7:$G$126,"DEZEMBRO",BASE!$H$7:$H$126,$E21) -> 0 | R21: =SUM(F21:Q21) -> 545390.97
E22: CONCEIÇÃO - 109 | F22: =SUMIFS(BASE!$L$7:$L$126,BASE!$G$7:$G$126,"JANEIRO",BASE!$H$7:$H$126,$E22) -> 87927.27 | G22: =SUMIFS(BASE!$L$7:$L$126,BASE!$G$7:$G$126,"FEVEREIRO",BASE!$H$7:$H$126,$E22) -> 61886.97 | H22: =SUMIFS(BASE!$L$7:$L$126,BASE!$G$7:$G$126,"MARÇO",BASE!$H$7:$H$126,$E22) -> 111317.47 | I22: =SUMIFS(BASE!$L$7:$L$126,BASE!$G$7:$G$126,"ABRIL",BASE!$H$7:$H$126,$E22) -> 104741.32 | J22: =SUMIFS(BASE!$L$7:$L$126,BASE!$G$7:$G$126,"MAIO",BASE!$H$7:$H$126,$E22) -> 102588.12 | K22: =SUMIFS(BASE!$L$7:$L$126,BASE!$G$7:$G$126,"JUNHO",BASE!$H$7:$H$126,$E22) -> 0 | L22: =SUMIFS(BASE!$L$7:$L$126,BASE!$G$7:$G$126,"JULHO",BASE!$H$7:$H$126,$E22) -> 0 | M22: =SUMIFS(BASE!$L$7:$L$126,BASE!$G$7:$G$126,"AGOSTO",BASE!$H$7:$H$126,$E22) -> 0 | N22: =SUMIFS(BASE!$L$7:$L$126,BASE!$G$7:$G$126,"SETEMBRO",BASE!$H$7:$H$126,$E22) -> 0 | O22: =SUMIFS(BASE!$L$7:$L$126,BASE!$G$7:$G$126,"OUTUBRO",BASE!$H$7:$H$126,$E22) -> 0 | P22: =SUMIFS(BASE!$L$7:$L$126,BASE!$G$7:$G$126,"NOVEMBRO",BASE!$H$7:$H$126,$E22) -> 0 | Q22: =SUMIFS(BASE!$L$7:$L$126,BASE!$G$7:$G$126,"DEZEMBRO",BASE!$H$7:$H$126,$E22) -> 0 | R22: =SUM(F22:Q22) -> 468461.15
E23: RIO BRANCO - 363 | F23: =SUMIFS(BASE!$L$7:$L$126,BASE!$G$7:$G$126,"JANEIRO",BASE!$H$7:$H$126,$E23) -> 127540.82 | G23: =SUMIFS(BASE!$L$7:$L$126,BASE!$G$7:$G$126,"FEVEREIRO",BASE!$H$7:$H$126,$E23) -> 94696.8 | H23: =SUMIFS(BASE!$L$7:$L$126,BASE!$G$7:$G$126,"MARÇO",BASE!$H$7:$H$126,$E23) -> 211346.6 | I23: =SUMIFS(BASE!$L$7:$L$126,BASE!$G$7:$G$126,"ABRIL",BASE!$H$7:$H$126,$E23) -> 141908.95 | J23: =SUMIFS(BASE!$L$7:$L$126,BASE!$G$7:$G$126,"MAIO",BASE!$H$7:$H$126,$E23) -> 135115.64 | K23: =SUMIFS(BASE!$L$7:$L$126,BASE!$G$7:$G$126,"JUNHO",BASE!$H$7:$H$126,$E23) -> 0 | L23: =SUMIFS(BASE!$L$7:$L$126,BASE!$G$7:$G$126,"JULHO",BASE!$H$7:$H$126,$E23) -> 0 | M23: =SUMIFS(BASE!$L$7:$L$126,BASE!$G$7:$G$126,"AGOSTO",BASE!$H$7:$H$126,$E23) -> 0 | N23: =SUMIFS(BASE!$L$7:$L$126,BASE!$G$7:$G$126,"SETEMBRO",BASE!$H$7:$H$126,$E23) -> 0 | O23: =SUMIFS(BASE!$L$7:$L$126,BASE!$G$7:$G$126,"OUTUBRO",BASE!$H$7:$H$126,$E23) -> 0 | P23: =SUMIFS(BASE!$L$7:$L$126,BASE!$G$7:$G$126,"NOVEMBRO",BASE!$H$7:$H$126,$E23) -> 0 | Q23: =SUMIFS(BASE!$L$7:$L$126,BASE!$G$7:$G$126,"DEZEMBRO",BASE!$H$7:$H$126,$E23) -> 0 | R23: =SUM(F23:Q23) -> 710608.81
E24: SÃO JOSÉ - 236 | F24: =SUMIFS(BASE!$L$7:$L$126,BASE!$G$7:$G$126,"JANEIRO",BASE!$H$7:$H$126,$E24) -> 80248.13 | G24: =SUMIFS(BASE!$L$7:$L$126,BASE!$G$7:$G$126,"FEVEREIRO",BASE!$H$7:$H$126,$E24) -> 58266.17 | H24: =SUMIFS(BASE!$L$7:$L$126,BASE!$G$7:$G$126,"MARÇO",BASE!$H$7:$H$126,$E24) -> 127108.93 | I24: =SUMIFS(BASE!$L$7:$L$126,BASE!$G$7:$G$126,"ABRIL",BASE!$H$7:$H$126,$E24) -> 92795.8 | J24: =SUMIFS(BASE!$L$7:$L$126,BASE!$G$7:$G$126,"MAIO",BASE!$H$7:$H$126,$E24) -> 91900.81 | K24: =SUMIFS(BASE!$L$7:$L$126,BASE!$G$7:$G$126,"JUNHO",BASE!$H$7:$H$126,$E24) -> 0 | L24: =SUMIFS(BASE!$L$7:$L$126,BASE!$G$7:$G$126,"JULHO",BASE!$H$7:$H$126,$E24) -> 0 | M24: =SUMIFS(BASE!$L$7:$L$126,BASE!$G$7:$G$126,"AGOSTO",BASE!$H$7:$H$126,$E24) -> 0 | N24: =SUMIFS(BASE!$L$7:$L$126,BASE!$G$7:$G$126,"SETEMBRO",BASE!$H$7:$H$126,$E24) -> 0 | O24: =SUMIFS(BASE!$L$7:$L$126,BASE!$G$7:$G$126,"OUTUBRO",BASE!$H$7:$H$126,$E24) -> 0 | P24: =SUMIFS(BASE!$L$7:$L$126,BASE!$G$7:$G$126,"NOVEMBRO",BASE!$H$7:$H$126,$E24) -> 0 | Q24: =SUMIFS(BASE!$L$7:$L$126,BASE!$G$7:$G$126,"DEZEMBRO",BASE!$H$7:$H$126,$E24) -> 0 | R24: =SUM(F24:Q24) -> 450319.84
E25: COPA 2 - 165 | F25: =SUMIFS(BASE!$L$7:$L$126,BASE!$G$7:$G$126,"JANEIRO",BASE!$H$7:$H$126,$E25) -> 134077.7 | G25: =SUMIFS(BASE!$L$7:$L$126,BASE!$G$7:$G$126,"FEVEREIRO",BASE!$H$7:$H$126,$E25) -> 107305.48 | H25: =SUMIFS(BASE!$L$7:$L$126,BASE!$G$7:$G$126,"MARÇO",BASE!$H$7:$H$126,$E25) -> 191891.56 | I25: =SUMIFS(BASE!$L$7:$L$126,BASE!$G$7:$G$126,"ABRIL",BASE!$H$7:$H$126,$E25) -> 163215.61 | J25: =SUMIFS(BASE!$L$7:$L$126,BASE!$G$7:$G$126,"MAIO",BASE!$H$7:$H$126,$E25) -> 113166.98 | K25: =SUMIFS(BASE!$L$7:$L$126,BASE!$G$7:$G$126,"JUNHO",BASE!$H$7:$H$126,$E25) -> 0 | L25: =SUMIFS(BASE!$L$7:$L$126,BASE!$G$7:$G$126,"JULHO",BASE!$H$7:$H$126,$E25) -> 0 | M25: =SUMIFS(BASE!$L$7:$L$126,BASE!$G$7:$G$126,"AGOSTO",BASE!$H$7:$H$126,$E25) -> 0 | N25: =SUMIFS(BASE!$L$7:$L$126,BASE!$G$7:$G$126,"SETEMBRO",BASE!$H$7:$H$126,$E25) -> 0 | O25: =SUMIFS(BASE!$L$7:$L$126,BASE!$G$7:$G$126,"OUTUBRO",BASE!$H$7:$H$126,$E25) -> 0 | P25: =SUMIFS(BASE!$L$7:$L$126,BASE!$G$7:$G$126,"NOVEMBRO",BASE!$H$7:$H$126,$E25) -> 0 | Q25: =SUMIFS(BASE!$L$7:$L$126,BASE!$G$7:$G$126,"DEZEMBRO",BASE!$H$7:$H$126,$E25) -> 0 | R25: =SUM(F25:Q25) -> 709657.33
E26: TIJUCA 3 - 157 | F26: =SUMIFS(BASE!$L$7:$L$126,BASE!$G$7:$G$126,"JANEIRO",BASE!$H$7:$H$126,$E26) -> 135322.99 | G26: =SUMIFS(BASE!$L$7:$L$126,BASE!$G$7:$G$126,"FEVEREIRO",BASE!$H$7:$H$126,$E26) -> 102918.8 | H26: =SUMIFS(BASE!$L$7:$L$126,BASE!$G$7:$G$126,"MARÇO",BASE!$H$7:$H$126,$E26) -> 189167.41 | I26: =SUMIFS(BASE!$L$7:$L$126,BASE!$G$7:$G$126,"ABRIL",BASE!$H$7:$H$126,$E26) -> 176400.42 | J26: =SUMIFS(BASE!$L$7:$L$126,BASE!$G$7:$G$126,"MAIO",BASE!$H$7:$H$126,$E26) -> 146808.19 | K26: =SUMIFS(BASE!$L$7:$L$126,BASE!$G$7:$G$126,"JUNHO",BASE!$H$7:$H$126,$E26) -> 0 | L26: =SUMIFS(BASE!$L$7:$L$126,BASE!$G$7:$G$126,"JULHO",BASE!$H$7:$H$126,$E26) -> 0 | M26: =SUMIFS(BASE!$L$7:$L$126,BASE!$G$7:$G$126,"AGOSTO",BASE!$H$7:$H$126,$E26) -> 0 | N26: =SUMIFS(BASE!$L$7:$L$126,BASE!$G$7:$G$126,"SETEMBRO",BASE!$H$7:$H$126,$E26) -> 0 | O26: =SUMIFS(BASE!$L$7:$L$126,BASE!$G$7:$G$126,"OUTUBRO",BASE!$H$7:$H$126,$E26) -> 0 | P26: =SUMIFS(BASE!$L$7:$L$126,BASE!$G$7:$G$126,"NOVEMBRO",BASE!$H$7:$H$126,$E26) -> 0 | Q26: =SUMIFS(BASE!$L$7:$L$126,BASE!$G$7:$G$126,"DEZEMBRO",BASE!$H$7:$H$126,$E26) -> 0 | R26: =SUM(F26:Q26) -> 750617.81
E27: RODRIGO SILVA - 997 | F27: =SUMIFS(BASE!$L$7:$L$126,BASE!$G$7:$G$126,"JANEIRO",BASE!$H$7:$H$126,$E27) -> 101310.26 | G27: =SUMIFS(BASE!$L$7:$L$126,BASE!$G$7:$G$126,"FEVEREIRO",BASE!$H$7:$H$126,$E27) -> 88651.15 | H27: =SUMIFS(BASE!$L$7:$L$126,BASE!$G$7:$G$126,"MARÇO",BASE!$H$7:$H$126,$E27) -> 166004.89 | I27: =SUMIFS(BASE!$L$7:$L$126,BASE!$G$7:$G$126,"ABRIL",BASE!$H$7:$H$126,$E27) -> 144467.88 | J27: =SUMIFS(BASE!$L$7:$L$126,BASE!$G$7:$G$126,"MAIO",BASE!$H$7:$H$126,$E27) -> 139354.01 | K27: =SUMIFS(BASE!$L$7:$L$126,BASE!$G$7:$G$126,"JUNHO",BASE!$H$7:$H$126,$E27) -> 0 | L27: =SUMIFS(BASE!$L$7:$L$126,BASE!$G$7:$G$126,"JULHO",BASE!$H$7:$H$126,$E27) -> 0 | M27: =SUMIFS(BASE!$L$7:$L$126,BASE!$G$7:$G$126,"AGOSTO",BASE!$H$7:$H$126,$E27) -> 0 | N27: =SUMIFS(BASE!$L$7:$L$126,BASE!$G$7:$G$126,"SETEMBRO",BASE!$H$7:$H$126,$E27) -> 0 | O27: =SUMIFS(BASE!$L$7:$L$126,BASE!$G$7:$G$126,"OUTUBRO",BASE!$H$7:$H$126,$E27) -> 0 | P27: =SUMIFS(BASE!$L$7:$L$126,BASE!$G$7:$G$126,"NOVEMBRO",BASE!$H$7:$H$126,$E27) -> 0 | Q27: =SUMIFS(BASE!$L$7:$L$126,BASE!$G$7:$G$126,"DEZEMBRO",BASE!$H$7:$H$126,$E27) -> 0 | R27: =SUM(F27:Q27) -> 639788.19
E28: RODO 3 - 1017 | F28: =SUMIFS(BASE!$L$7:$L$126,BASE!$G$7:$G$126,"JANEIRO",BASE!$H$7:$H$126,$E28) -> 152021.53 | G28: =SUMIFS(BASE!$L$7:$L$126,BASE!$G$7:$G$126,"FEVEREIRO",BASE!$H$7:$H$126,$E28) -> 108206.22 | H28: =SUMIFS(BASE!$L$7:$L$126,BASE!$G$7:$G$126,"MARÇO",BASE!$H$7:$H$126,$E28) -> 210418.91 | I28: =SUMIFS(BASE!$L$7:$L$126,BASE!$G$7:$G$126,"ABRIL",BASE!$H$7:$H$126,$E28) -> 185511.58 | J28: =SUMIFS(BASE!$L$7:$L$126,BASE!$G$7:$G$126,"MAIO",BASE!$H$7:$H$126,$E28) -> 171648.07 | K28: =SUMIFS(BASE!$L$7:$L$126,BASE!$G$7:$G$126,"JUNHO",BASE!$H$7:$H$126,$E28) -> 0 | L28: =SUMIFS(BASE!$L$7:$L$126,BASE!$G$7:$G$126,"JULHO",BASE!$H$7:$H$126,$E28) -> 0 | M28: =SUMIFS(BASE!$L$7:$L$126,BASE!$G$7:$G$126,"AGOSTO",BASE!$H$7:$H$126,$E28) -> 0 | N28: =SUMIFS(BASE!$L$7:$L$126,BASE!$G$7:$G$126,"SETEMBRO",BASE!$H$7:$H$126,$E28) -> 0 | O28: =SUMIFS(BASE!$L$7:$L$126,BASE!$G$7:$G$126,"OUTUBRO",BASE!$H$7:$H$126,$E28) -> 0 | P28: =SUMIFS(BASE!$L$7:$L$126,BASE!$G$7:$G$126,"NOVEMBRO",BASE!$H$7:$H$126,$E28) -> 0 | Q28: =SUMIFS(BASE!$L$7:$L$126,BASE!$G$7:$G$126,"DEZEMBRO",BASE!$H$7:$H$126,$E28) -> 0 | R28: =SUM(F28:Q28) -> 827806.31
E29: TOTAL | F29: =SUM(F19:F28) -> 1035086.7 | G29: =SUM(G19:G28) -> 791620.54 | H29: =SUM(H19:H28) -> 1504070.6 | I29: =SUM(I19:I28) -> 1268293.6 | J29: =SUM(J19:J28) -> 1145894.7 | K29: =SUM(K19:K28) -> 0 | L29: =SUM(L19:L28) -> 0 | M29: =SUM(M19:M28) -> 0 | ... R29: =SUM(R19:R28) -> 5744966.1
E31: % DA META 1
E32: LOJA | F32: JAN | G32: FEV | H32: MAR | I32: ABR | J32: MAI | K32: JUN | L32: JUL | M32: AGO | N32: SET | O32: OUT | P32: NOV | Q32: DEZ | R32: ANO
E33: ITABORAÍ 2 - 257 | F33: =IFERROR(SUMIFS(BASE!$L$7:$L$126,BASE!$G$7:$G$126,"JANEIRO",BASE!$H$7:$H$126,$E33)/SUMIFS(BASE!$K$7:$K$126,BASE!$G$7:$G$126,"JANEIRO",BASE!$H$7:$H$126,$E33),"") -> 1.1006966 | G33: =IFERROR(SUMIFS(BASE!$L$7:$L$126,BASE!$G$7:$G$126,"FEVEREIRO",BASE!$H$7:$H$126,$E33)/SUMIFS(BASE!$K$7:$K$126,BASE!$G$7:$G$126,"FEVEREIRO",BASE!$H$7:$H$126,$E33),"") -> 0.68666064 | H33: =IFERROR(SUMIFS(BASE!$L$7:$L$126,BASE!$G$7:$G$126,"MARÇO",BASE!$H$7:$H$126,$E33)/SUMIFS(BASE!$K$7:$K$126,BASE!$G$7:$G$126,"MARÇO",BASE!$H$7:$H$126,$E33),"") -> 1.0726231 | I33: =IFERROR(SUMIFS(BASE!$L$7:$L$126,BASE!$G$7:$G$126,"ABRIL",BASE!$H$7:$H$126,$E33)/SUMIFS(BASE!$K$7:$K$126,BASE!$G$7:$G$126,"ABRIL",BASE!$H$7:$H$126,$E33),"") -> 0.880049 | J33: =IFERROR(SUMIFS(BASE!$L$7:$L$126,BASE!$G$7:$G$126,"MAIO",BASE!$H$7:$H$126,$E33)/SUMIFS(BASE!$K$7:$K$126,BASE!$G$7:$G$126,"MAIO",BASE!$H$7:$H$126,$E33),"") -> 0.6397961 | K33: =IFERROR(SUMIFS(BASE!$L$7:$L$126,BASE!$G$7:$G$126,"JUNHO",BASE!$H$7:$H$126,$E33)/SUMIFS(BASE!$K$7:$K$126,BASE!$G$7:$G$126,"JUNHO",BASE!$H$7:$H$126,$E33),"") | L33: =IFERROR(SUMIFS(BASE!$L$7:$L$126,BASE!$G$7:$G$126,"JULHO",BASE!$H$7:$H$126,$E33)/SUMIFS(BASE!$K$7:$K$126,BASE!$G$7:$G$126,"JULHO",BASE!$H$7:$H$126,$E33),"") | M33: =IFERROR(SUMIFS(BASE!$L$7:$L$126,BASE!$G$7:$G$126,"AGOSTO",BASE!$H$7:$H$126,$E33)/SUMIFS(BASE!$K$7:$K$126,BASE!$G$7:$G$126,"AGOSTO",BASE!$H$7:$H$126,$E33),"") | N33: =IFERROR(SUMIFS(BASE!$L$7:$L$126,BASE!$G$7:$G$126,"SETEMBRO",BASE!$H$7:$H$126,$E33)/SUMIFS(BASE!$K$7:$K$126,BASE!$G$7:$G$126,"SETEMBRO",BASE!$H$7:$H$126,$E33),"") | O33: =IFERROR(SUMIFS(BASE!$L$7:$L$126,BASE!$G$7:$G$126,"OUTUBRO",BASE!$H$7:$H$126,$E33)/SUMIFS(BASE!$K$7:$K$126,BASE!$G$7:$G$126,"OUTUBRO",BASE!$H$7:$H$126,$E33),"") | P33: =IFERROR(SUMIFS(BASE!$L$7:$L$126,BASE!$G$7:$G$126,"NOVEMBRO",BASE!$H$7:$H$126,$E33)/SUMIFS(BASE!$K$7:$K$126,BASE!$G$7:$G$126,"NOVEMBRO",BASE!$H$7:$H$126,$E33),"") | Q33: =IFERROR(SUMIFS(BASE!$L$7:$L$126,BASE!$G$7:$G$126,"DEZEMBRO",BASE!$H$7:$H$126,$E33)/SUMIFS(BASE!$K$7:$K$126,BASE!$G$7:$G$126,"DEZEMBRO",BASE!$H$7:$H$126,$E33),"") | R33: =IFERROR(SUMIFS(BASE!$L$7:$L$126,BASE!$H$7:$H$126,$E33)/SUMIFS(BASE!$K$7:$K$126,BASE!$H$7:$H$126,$E33),"") -> 0.84326598
E34: SÃO GONÇALO - 364 | F34: =IFERROR(SUMIFS(BASE!$L$7:$L$126,BASE!$G$7:$G$126,"JANEIRO",BASE!$H$7:$H$126,$E34)/SUMIFS(BASE!$K$7:$K$126,BASE!$G$7:$G$126,"JANEIRO",BASE!$H$7:$H$126,$E34),"") | G34: =IFERROR(SUMIFS(BASE!$L$7:$L$126,BASE!$G$7:$G$126,"FEVEREIRO",BASE!$H$7:$H$126,$E34)/SUMIFS(BASE!$K$7:$K$126,BASE!$G$7:$G$126,"FEVEREIRO",BASE!$H$7:$H$126,$E34),"") | H34: =IFERROR(SUMIFS(BASE!$L$7:$L$126,BASE!$G$7:$G$126,"MARÇO",BASE!$H$7:$H$126,$E34)/SUMIFS(BASE!$K$7:$K$126,BASE!$G$7:$G$126,"MARÇO",BASE!$H$7:$H$126,$E34),"") | I34: =IFERROR(SUMIFS(BASE!$L$7:$L$126,BASE!$G$7:$G$126,"ABRIL",BASE!$H$7:$H$126,$E34)/SUMIFS(BASE!$K$7:$K$126,BASE!$G$7:$G$126,"ABRIL",BASE!$H$7:$H$126,$E34),"") | J34: =IFERROR(SUMIFS(BASE!$L$7:$L$126,BASE!$G$7:$G$126,"MAIO",BASE!$H$7:$H$126,$E34)/SUMIFS(BASE!$K$7:$K$126,BASE!$G$7:$G$126,"MAIO",BASE!$H$7:$H$126,$E34),"") | K34: =IFERROR(SUMIFS(BASE!$L$7:$L$126,BASE!$G$7:$G$126,"JUNHO",BASE!$H$7:$H$126,$E34)/SUMIFS(BASE!$K$7:$K$126,BASE!$G$7:$G$126,"JUNHO",BASE!$H$7:$H$126,$E34),"") | L34: =IFERROR(SUMIFS(BASE!$L$7:$L$126,BASE!$G$7:$G$126,"JULHO",BASE!$H$7:$H$126,$E34)/SUMIFS(BASE!$K$7:$K$126,BASE!$G$7:$G$126,"JULHO",BASE!$H$7:$H$126,$E34),"") | M34: =IFERROR(SUMIFS(BASE!$L$7:$L$126,BASE!$G$7:$G$126,"AGOSTO",BASE!$H$7:$H$126,$E34)/SUMIFS(BASE!$K$7:$K$126,BASE!$G$7:$G$126,"AGOSTO",BASE!$H$7:$H$126,$E34),"") | N34: =IFERROR(SUMIFS(BASE!$L$7:$L$126,BASE!$G$7:$G$126,"SETEMBRO",BASE!$H$7:$H$126,$E34)/SUMIFS(BASE!$K$7:$K$126,BASE!$G$7:$G$126,"SETEMBRO",BASE!$H$7:$H$126,$E34),"") | O34: =IFERROR(SUMIFS(BASE!$L$7:$L$126,BASE!$G$7:$G$126,"OUTUBRO",BASE!$H$7:$H$126,$E34)/SUMIFS(BASE!$K$7:$K$126,BASE!$G$7:$G$126,"OUTUBRO",BASE!$H$7:$H$126,$E34),"") | P34: =IFERROR(SUMIFS(BASE!$L$7:$L$126,BASE!$G$7:$G$126,"NOVEMBRO",BASE!$H$7:$H$126,$E34)/SUMIFS(BASE!$K$7:$K$126,BASE!$G$7:$G$126,"NOVEMBRO",BASE!$H$7:$H$126,$E34),"") | Q34: =IFERROR(SUMIFS(BASE!$L$7:$L$126,BASE!$G$7:$G$126,"DEZEMBRO",BASE!$H$7:$H$126,$E34)/SUMIFS(BASE!$K$7:$K$126,BASE!$G$7:$G$126,"DEZEMBRO",BASE!$H$7:$H$126,$E34),"") | R34: =IFERROR(SUMIFS(BASE!$L$7:$L$126,BASE!$H$7:$H$126,$E34)/SUMIFS(BASE!$K$7:$K$126,BASE!$H$7:$H$126,$E34),"")
E35: CENTER 4 - 117 | F35: =IFERROR(SUMIFS(BASE!$L$7:$L$126,BASE!$G$7:$G$126,"JANEIRO",BASE!$H$7:$H$126,$E35)/SUMIFS(BASE!$K$7:$K$126,BASE!$G$7:$G$126,"JANEIRO",BASE!$H$7:$H$126,$E35),"") -> 0.8452155 | G35: =IFERROR(SUMIFS(BASE!$L$7:$L$126,BASE!$G$7:$G$126,"FEVEREIRO",BASE!$H$7:$H$126,$E35)/SUMIFS(BASE!$K$7:$K$126,BASE!$G$7:$G$126,"FEVEREIRO",BASE!$H$7:$H$126,$E35),"") -> 0.70862233 | H35: =IFERROR(SUMIFS(BASE!$L$7:$L$126,BASE!$G$7:$G$126,"MARÇO",BASE!$H$7:$H$126,$E35)/SUMIFS(BASE!$K$7:$K$126,BASE!$G$7:$G$126,"MARÇO",BASE!$H$7:$H$126,$E35),"") -> 1.0455492 | I35: =IFERROR(SUMIFS(BASE!$L$7:$L$126,BASE!$G$7:$G$126,"ABRIL",BASE!$H$7:$H$126,$E35)/SUMIFS(BASE!$K$7:$K$126,BASE!$G$7:$G$126,"ABRIL",BASE!$H$7:$H$126,$E35),"") -> 1.0260672 | J35: =IFERROR(SUMIFS(BASE!$L$7:$L$126,BASE!$G$7:$G$126,"MAIO",BASE!$H$7:$H$126,$E35)/SUMIFS(BASE!$K$7:$K$126,BASE!$G$7:$G$126,"MAIO",BASE!$H$7:$H$126,$E35),"") -> 0.57241118 | K35: =IFERROR(SUMIFS(BASE!$L$7:$L$126,BASE!$G$7:$G$126,"JUNHO",BASE!$H$7:$H$126,$E35)/SUMIFS(BASE!$K$7:$K$126,BASE!$G$7:$G$126,"JUNHO",BASE!$H$7:$H$126,$E35),"") | L35: =IFERROR(SUMIFS(BASE!$L$7:$L$126,BASE!$G$7:$G$126,"JULHO",BASE!$H$7:$H$126,$E35)/SUMIFS(BASE!$K$7:$K$126,BASE!$G$7:$G$126,"JULHO",BASE!$H$7:$H$126,$E35),"") | M35: =IFERROR(SUMIFS(BASE!$L$7:$L$126,BASE!$G$7:$G$126,"AGOSTO",BASE!$H$7:$H$126,$E35)/SUMIFS(BASE!$K$7:$K$126,BASE!$G$7:$G$126,"AGOSTO",BASE!$H$7:$H$126,$E35),"") | N35: =IFERROR(SUMIFS(BASE!$L$7:$L$126,BASE!$G$7:$G$126,"SETEMBRO",BASE!$H$7:$H$126,$E35)/SUMIFS(BASE!$K$7:$K$126,BASE!$G$7:$G$126,"SETEMBRO",BASE!$H$7:$H$126,$E35),"") | O35: =IFERROR(SUMIFS(BASE!$L$7:$L$126,BASE!$G$7:$G$126,"OUTUBRO",BASE!$H$7:$H$126,$E35)/SUMIFS(BASE!$K$7:$K$126,BASE!$G$7:$G$126,"OUTUBRO",BASE!$H$7:$H$126,$E35),"") | P35: =IFERROR(SUMIFS(BASE!$L$7:$L$126,BASE!$G$7:$G$126,"NOVEMBRO",BASE!$H$7:$H$126,$E35)/SUMIFS(BASE!$K$7:$K$126,BASE!$G$7:$G$126,"NOVEMBRO",BASE!$H$7:$H$126,$E35),"") | Q35: =IFERROR(SUMIFS(BASE!$L$7:$L$126,BASE!$G$7:$G$126,"DEZEMBRO",BASE!$H$7:$H$126,$E35)/SUMIFS(BASE!$K$7:$K$126,BASE!$G$7:$G$126,"DEZEMBRO",BASE!$H$7:$H$126,$E35),"") | R35: =IFERROR(SUMIFS(BASE!$L$7:$L$126,BASE!$H$7:$H$126,$E35)/SUMIFS(BASE!$K$7:$K$126,BASE!$H$7:$H$126,$E35),"") -> 0.82471053
E36: CONCEIÇÃO - 109 | F36: =IFERROR(SUMIFS(BASE!$L$7:$L$126,BASE!$G$7:$G$126,"JANEIRO",BASE!$H$7:$H$126,$E36)/SUMIFS(BASE!$K$7:$K$126,BASE!$G$7:$G$126,"JANEIRO",BASE!$H$7:$H$126,$E36),"") -> 0.86885513 | G36: =IFERROR(SUMIFS(BASE!$L$7:$L$126,BASE!$G$7:$G$126,"FEVEREIRO",BASE!$H$7:$H$126,$E36)/SUMIFS(BASE!$K$7:$K$126,BASE!$G$7:$G$126,"FEVEREIRO",BASE!$H$7:$H$126,$E36),"") -> 0.56260882 | H36: =IFERROR(SUMIFS(BASE!$L$7:$L$126,BASE!$G$7:$G$126,"MARÇO",BASE!$H$7:$H$126,$E36)/SUMIFS(BASE!$K$7:$K$126,BASE!$G$7:$G$126,"MARÇO",BASE!$H$7:$H$126,$E36),"") -> 1.0721231 | I36: =IFERROR(SUMIFS(BASE!$L$7:$L$126,BASE!$G$7:$G$126,"ABRIL",BASE!$H$7:$H$126,$E36)/SUMIFS(BASE!$K$7:$K$126,BASE!$G$7:$G$126,"ABRIL",BASE!$H$7:$H$126,$E36),"") -> 0.87284433 | J36: =IFERROR(SUMIFS(BASE!$L$7:$L$126,BASE!$G$7:$G$126,"MAIO",BASE!$H$7:$H$126,$E36)/SUMIFS(BASE!$K$7:$K$126,BASE!$G$7:$G$126,"MAIO",BASE!$H$7:$H$126,$E36),"") -> 0.60488992 | K36: =IFERROR(SUMIFS(BASE!$L$7:$L$126,BASE!$G$7:$G$126,"JUNHO",BASE!$H$7:$H$126,$E36)/SUMIFS(BASE!$K$7:$K$126,BASE!$G$7:$G$126,"JUNHO",BASE!$H$7:$H$126,$E36),"") | L36: =IFERROR(SUMIFS(BASE!$L$7:$L$126,BASE!$G$7:$G$126,"JULHO",BASE!$H$7:$H$126,$E36)/SUMIFS(BASE!$K$7:$K$126,BASE!$G$7:$G$126,"JULHO",BASE!$H$7:$H$126,$E36),"") | M36: =IFERROR(SUMIFS(BASE!$L$7:$L$126,BASE!$G$7:$G$126,"AGOSTO",BASE!$H$7:$H$126,$E36)/SUMIFS(BASE!$K$7:$K$126,BASE!$G$7:$G$126,"AGOSTO",BASE!$H$7:$H$126,$E36),"") | N36: =IFERROR(SUMIFS(BASE!$L$7:$L$126,BASE!$G$7:$G$126,"SETEMBRO",BASE!$H$7:$H$126,$E36)/SUMIFS(BASE!$K$7:$K$126,BASE!$G$7:$G$126,"SETEMBRO",BASE!$H$7:$H$126,$E36),"") | O36: =IFERROR(SUMIFS(BASE!$L$7:$L$126,BASE!$G$7:$G$126,"OUTUBRO",BASE!$H$7:$H$126,$E36)/SUMIFS(BASE!$K$7:$K$126,BASE!$G$7:$G$126,"OUTUBRO",BASE!$H$7:$H$126,$E36),"") | P36: =IFERROR(SUMIFS(BASE!$L$7:$L$126,BASE!$G$7:$G$126,"NOVEMBRO",BASE!$H$7:$H$126,$E36)/SUMIFS(BASE!$K$7:$K$126,BASE!$G$7:$G$126,"NOVEMBRO",BASE!$H$7:$H$126,$E36),"") | Q36: =IFERROR(SUMIFS(BASE!$L$7:$L$126,BASE!$G$7:$G$126,"DEZEMBRO",BASE!$H$7:$H$126,$E36)/SUMIFS(BASE!$K$7:$K$126,BASE!$G$7:$G$126,"DEZEMBRO",BASE!$H$7:$H$126,$E36),"") | R36: =IFERROR(SUMIFS(BASE!$L$7:$L$126,BASE!$H$7:$H$126,$E36)/SUMIFS(BASE!$K$7:$K$126,BASE!$H$7:$H$126,$E36),"") -> 0.77479491
E37: RIO BRANCO - 363 | F37: =IFERROR(SUMIFS(BASE!$L$7:$L$126,BASE!$G$7:$G$126,"JANEIRO",BASE!$H$7:$H$126,$E37)/SUMIFS(BASE!$K$7:$K$126,BASE!$G$7:$G$126,"JANEIRO",BASE!$H$7:$H$126,$E37),"") -> 0.62132595 | G37: =IFERROR(SUMIFS(BASE!$L$7:$L$126,BASE!$G$7:$G$126,"FEVEREIRO",BASE!$H$7:$H$126,$E37)/SUMIFS(BASE!$K$7:$K$126,BASE!$G$7:$G$126,"FEVEREIRO",BASE!$H$7:$H$126,$E37),"") -> 0.59934684 | H37: =IFERROR(SUMIFS(BASE!$L$7:$L$126,BASE!$G$7:$G$126,"MARÇO",BASE!$H$7:$H$126,$E37)/SUMIFS(BASE!$K$7:$K$126,BASE!$G$7:$G$126,"MARÇO",BASE!$H$7:$H$126,$E37),"") -> 1.3635265 | I37: =IFERROR(SUMIFS(BASE!$L$7:$L$126,BASE!$G$7:$G$126,"ABRIL",BASE!$H$7:$H$126,$E37)/SUMIFS(BASE!$K$7:$K$126,BASE!$G$7:$G$126,"ABRIL",BASE!$H$7:$H$126,$E37),"") -> 0.78838306 | J37: =IFERROR(SUMIFS(BASE!$L$7:$L$126,BASE!$G$7:$G$126,"MAIO",BASE!$H$7:$H$126,$E37)/SUMIFS(BASE!$K$7:$K$126,BASE!$G$7:$G$126,"MAIO",BASE!$H$7:$H$126,$E37),"") -> 0.614162 | K37: =IFERROR(SUMIFS(BASE!$L$7:$L$126,BASE!$G$7:$G$126,"JUNHO",BASE!$H$7:$H$126,$E37)/SUMIFS(BASE!$K$7:$K$126,BASE!$G$7:$G$126,"JUNHO",BASE!$H$7:$H$126,$E37),"") | L37: =IFERROR(SUMIFS(BASE!$L$7:$L$126,BASE!$G$7:$G$126,"JULHO",BASE!$H$7:$H$126,$E37)/SUMIFS(BASE!$K$7:$K$126,BASE!$G$7:$G$126,"JULHO",BASE!$H$7:$H$126,$E37),"") | M37: =IFERROR(SUMIFS(BASE!$L$7:$L$126,BASE!$G$7:$G$126,"AGOSTO",BASE!$H$7:$H$126,$E37)/SUMIFS(BASE!$K$7:$K$126,BASE!$G$7:$G$126,"AGOSTO",BASE!$H$7:$H$126,$E37),"") | N37: =IFERROR(SUMIFS(BASE!$L$7:$L$126,BASE!$G$7:$G$126,"SETEMBRO",BASE!$H$7:$H$126,$E37)/SUMIFS(BASE!$K$7:$K$126,BASE!$G$7:$G$126,"SETEMBRO",BASE!$H$7:$H$126,$E37),"") | O37: =IFERROR(SUMIFS(BASE!$L$7:$L$126,BASE!$G$7:$G$126,"OUTUBRO",BASE!$H$7:$H$126,$E37)/SUMIFS(BASE!$K$7:$K$126,BASE!$G$7:$G$126,"OUTUBRO",BASE!$H$7:$H$126,$E37),"") | P37: =IFERROR(SUMIFS(BASE!$L$7:$L$126,BASE!$G$7:$G$126,"NOVEMBRO",BASE!$H$7:$H$126,$E37)/SUMIFS(BASE!$K$7:$K$126,BASE!$G$7:$G$126,"NOVEMBRO",BASE!$H$7:$H$126,$E37),"") | Q37: =IFERROR(SUMIFS(BASE!$L$7:$L$126,BASE!$G$7:$G$126,"DEZEMBRO",BASE!$H$7:$H$126,$E37)/SUMIFS(BASE!$K$7:$K$126,BASE!$G$7:$G$126,"DEZEMBRO",BASE!$H$7:$H$126,$E37),"") | R37: =IFERROR(SUMIFS(BASE!$L$7:$L$126,BASE!$H$7:$H$126,$E37)/SUMIFS(BASE!$K$7:$K$126,BASE!$H$7:$H$126,$E37),"") -> 0.77385438
E38: SÃO JOSÉ - 236 | F38: =IFERROR(SUMIFS(BASE!$L$7:$L$126,BASE!$G$7:$G$126,"JANEIRO",BASE!$H$7:$H$126,$E38)/SUMIFS(BASE!$K$7:$K$126,BASE!$G$7:$G$126,"JANEIRO",BASE!$H$7:$H$126,$E38),"") -> 0.72952845 | G38: =IFERROR(SUMIFS(BASE!$L$7:$L$126,BASE!$G$7:$G$126,"FEVEREIRO",BASE!$H$7:$H$126,$E38)/SUMIFS(BASE!$K$7:$K$126,BASE!$G$7:$G$126,"FEVEREIRO",BASE!$H$7:$H$126,$E38),"") -> 0.5549159 | H38: =IFERROR(SUMIFS(BASE!$L$7:$L$126,BASE!$G$7:$G$126,"MARÇO",BASE!$H$7:$H$126,$E38)/SUMIFS(BASE!$K$7:$K$126,BASE!$G$7:$G$126,"MARÇO",BASE!$H$7:$H$126,$E38),"") -> 1.3899434 | I38: =IFERROR(SUMIFS(BASE!$L$7:$L$126,BASE!$G$7:$G$126,"ABRIL",BASE!$H$7:$H$126,$E38)/SUMIFS(BASE!$K$7:$K$126,BASE!$G$7:$G$126,"ABRIL",BASE!$H$7:$H$126,$E38),"") -> 0.80692 | J38: =IFERROR(SUMIFS(BASE!$L$7:$L$126,BASE!$G$7:$G$126,"MAIO",BASE!$H$7:$H$126,$E38)/SUMIFS(BASE!$K$7:$K$126,BASE!$G$7:$G$126,"MAIO",BASE!$H$7:$H$126,$E38),"") -> 0.60126408 | K38: =IFERROR(SUMIFS(BASE!$L$7:$L$126,BASE!$G$7:$G$126,"JUNHO",BASE!$H$7:$H$126,$E38)/SUMIFS(BASE!$K$7:$K$126,BASE!$G$7:$G$126,"JUNHO",BASE!$H$7:$H$126,$E38),"") | L38: =IFERROR(SUMIFS(BASE!$L$7:$L$126,BASE!$G$7:$G$126,"JULHO",BASE!$H$7:$H$126,$E38)/SUMIFS(BASE!$K$7:$K$126,BASE!$G$7:$G$126,"JULHO",BASE!$H$7:$H$126,$E38),"") | M38: =IFERROR(SUMIFS(BASE!$L$7:$L$126,BASE!$G$7:$G$126,"AGOSTO",BASE!$H$7:$H$126,$E38)/SUMIFS(BASE!$K$7:$K$126,BASE!$G$7:$G$126,"AGOSTO",BASE!$H$7:$H$126,$E38),"") | N38: =IFERROR(SUMIFS(BASE!$L$7:$L$126,BASE!$G$7:$G$126,"SETEMBRO",BASE!$H$7:$H$126,$E38)/SUMIFS(BASE!$K$7:$K$126,BASE!$G$7:$G$126,"SETEMBRO",BASE!$H$7:$H$126,$E38),"") | O38: =IFERROR(SUMIFS(BASE!$L$7:$L$126,BASE!$G$7:$G$126,"OUTUBRO",BASE!$H$7:$H$126,$E38)/SUMIFS(BASE!$K$7:$K$126,BASE!$G$7:$G$126,"OUTUBRO",BASE!$H$7:$H$126,$E38),"") | P38: =IFERROR(SUMIFS(BASE!$L$7:$L$126,BASE!$G$7:$G$126,"NOVEMBRO",BASE!$H$7:$H$126,$E38)/SUMIFS(BASE!$K$7:$K$126,BASE!$G$7:$G$126,"NOVEMBRO",BASE!$H$7:$H$126,$E38),"") | Q38: =IFERROR(SUMIFS(BASE!$L$7:$L$126,BASE!$G$7:$G$126,"DEZEMBRO",BASE!$H$7:$H$126,$E38)/SUMIFS(BASE!$K$7:$K$126,BASE!$G$7:$G$126,"DEZEMBRO",BASE!$H$7:$H$126,$E38),"") | R38: =IFERROR(SUMIFS(BASE!$L$7:$L$126,BASE!$H$7:$H$126,$E38)/SUMIFS(BASE!$K$7:$K$126,BASE!$H$7:$H$126,$E38),"") -> 0.78412635
E39: COPA 2 - 165 | F39: =IFERROR(SUMIFS(BASE!$L$7:$L$126,BASE!$G$7:$G$126,"JANEIRO",BASE!$H$7:$H$126,$E39)/SUMIFS(BASE!$K$7:$K$126,BASE!$G$7:$G$126,"JANEIRO",BASE!$H$7:$H$126,$E39),"") -> 0.74487611 | G39: =IFERROR(SUMIFS(BASE!$L$7:$L$126,BASE!$G$7:$G$126,"FEVEREIRO",BASE!$H$7:$H$126,$E39)/SUMIFS(BASE!$K$7:$K$126,BASE!$G$7:$G$126,"FEVEREIRO",BASE!$H$7:$H$126,$E39),"") -> 0.6387231 | H39: =IFERROR(SUMIFS(BASE!$L$7:$L$126,BASE!$G$7:$G$126,"MARÇO",BASE!$H$7:$H$126,$E39)/SUMIFS(BASE!$K$7:$K$126,BASE!$G$7:$G$126,"MARÇO",BASE!$H$7:$H$126,$E39),"") -> 1.0660642 | I39: =IFERROR(SUMIFS(BASE!$L$7:$L$126,BASE!$G$7:$G$126,"ABRIL",BASE!$H$7:$H$126,$E39)/SUMIFS(BASE!$K$7:$K$126,BASE!$G$7:$G$126,"ABRIL",BASE!$H$7:$H$126,$E39),"") -> 0.93532765 | J39: =IFERROR(SUMIFS(BASE!$L$7:$L$126,BASE!$G$7:$G$126,"MAIO",BASE!$H$7:$H$126,$E39)/SUMIFS(BASE!$K$7:$K$126,BASE!$G$7:$G$126,"MAIO",BASE!$H$7:$H$126,$E39),"") -> 0.5658349 | K39: =IFERROR(SUMIFS(BASE!$L$7:$L$126,BASE!$G$7:$G$126,"JUNHO",BASE!$H$7:$H$126,$E39)/SUMIFS(BASE!$K$7:$K$126,BASE!$G$7:$G$126,"JUNHO",BASE!$H$7:$H$126,$E39),"") | L39: =IFERROR(SUMIFS(BASE!$L$7:$L$126,BASE!$G$7:$G$126,"JULHO",BASE!$H$7:$H$126,$E39)/SUMIFS(BASE!$K$7:$K$126,BASE!$G$7:$G$126,"JULHO",BASE!$H$7:$H$126,$E39),"") | M39: =IFERROR(SUMIFS(BASE!$L$7:$L$126,BASE!$G$7:$G$126,"AGOSTO",BASE!$H$7:$H$126,$E39)/SUMIFS(BASE!$K$7:$K$126,BASE!$G$7:$G$126,"AGOSTO",BASE!$H$7:$H$126,$E39),"") | N39: =IFERROR(SUMIFS(BASE!$L$7:$L$126,BASE!$G$7:$G$126,"SETEMBRO",BASE!$H$7:$H$126,$E39)/SUMIFS(BASE!$K$7:$K$126,BASE!$G$7:$G$126,"SETEMBRO",BASE!$H$7:$H$126,$E39),"") | O39: =IFERROR(SUMIFS(BASE!$L$7:$L$126,BASE!$G$7:$G$126,"OUTUBRO",BASE!$H$7:$H$126,$E39)/SUMIFS(BASE!$K$7:$K$126,BASE!$G$7:$G$126,"OUTUBRO",BASE!$H$7:$H$126,$E39),"") | P39: =IFERROR(SUMIFS(BASE!$L$7:$L$126,BASE!$G$7:$G$126,"NOVEMBRO",BASE!$H$7:$H$126,$E39)/SUMIFS(BASE!$K$7:$K$126,BASE!$G$7:$G$126,"NOVEMBRO",BASE!$H$7:$H$126,$E39),"") | Q39: =IFERROR(SUMIFS(BASE!$L$7:$L$126,BASE!$G$7:$G$126,"DEZEMBRO",BASE!$H$7:$H$126,$E39)/SUMIFS(BASE!$K$7:$K$126,BASE!$G$7:$G$126,"DEZEMBRO",BASE!$H$7:$H$126,$E39),"") | R39: =IFERROR(SUMIFS(BASE!$L$7:$L$126,BASE!$H$7:$H$126,$E39)/SUMIFS(BASE!$K$7:$K$126,BASE!$H$7:$H$126,$E39),"") -> 0.78632304
E40: TIJUCA 3 - 157 | F40: =IFERROR(SUMIFS(BASE!$L$7:$L$126,BASE!$G$7:$G$126,"JANEIRO",BASE!$H$7:$H$126,$E40)/SUMIFS(BASE!$K$7:$K$126,BASE!$G$7:$G$126,"JANEIRO",BASE!$H$7:$H$126,$E40),"") -> 0.954471 | G40: =IFERROR(SUMIFS(BASE!$L$7:$L$126,BASE!$G$7:$G$126,"FEVEREIRO",BASE!$H$7:$H$126,$E40)/SUMIFS(BASE!$K$7:$K$126,BASE!$G$7:$G$126,"FEVEREIRO",BASE!$H$7:$H$126,$E40),"") -> 0.6237503 | H40: =IFERROR(SUMIFS(BASE!$L$7:$L$126,BASE!$G$7:$G$126,"MARÇO",BASE!$H$7:$H$126,$E40)/SUMIFS(BASE!$K$7:$K$126,BASE!$G$7:$G$126,"MARÇO",BASE!$H$7:$H$126,$E40),"") -> 1.2370351 | I40: =IFERROR(SUMIFS(BASE!$L$7:$L$126,BASE!$G$7:$G$126,"ABRIL",BASE!$H$7:$H$126,$E40)/SUMIFS(BASE!$K$7:$K$126,BASE!$G$7:$G$126,"ABRIL",BASE!$H$7:$H$126,$E40),"") -> 1.0314065 | J40: =IFERROR(SUMIFS(BASE!$L$7:$L$126,BASE!$G$7:$G$126,"MAIO",BASE!$H$7:$H$126,$E40)/SUMIFS(BASE!$K$7:$K$126,BASE!$G$7:$G$126,"MAIO",BASE!$H$7:$H$126,$E40),"") -> 0.62303748 | K40: =IFERROR(SUMIFS(BASE!$L$7:$L$126,BASE!$G$7:$G$126,"JUNHO",BASE!$H$7:$H$126,$E40)/SUMIFS(BASE!$K$7:$K$126,BASE!$G$7:$G$126,"JUNHO",BASE!$H$7:$H$126,$E40),"") | L40: =IFERROR(SUMIFS(BASE!$L$7:$L$126,BASE!$G$7:$G$126,"JULHO",BASE!$H$7:$H$126,$E40)/SUMIFS(BASE!$K$7:$K$126,BASE!$G$7:$G$126,"JULHO",BASE!$H$7:$H$126,$E40),"") | M40: =IFERROR(SUMIFS(BASE!$L$7:$L$126,BASE!$G$7:$G$126,"AGOSTO",BASE!$H$7:$H$126,$E40)/SUMIFS(BASE!$K$7:$K$126,BASE!$G$7:$G$126,"AGOSTO",BASE!$H$7:$H$126,$E40),"") | N40: =IFERROR(SUMIFS(BASE!$L$7:$L$126,BASE!$G$7:$G$126,"SETEMBRO",BASE!$H$7:$H$126,$E40)/SUMIFS(BASE!$K$7:$K$126,BASE!$G$7:$G$126,"SETEMBRO",BASE!$H$7:$H$126,$E40),"") | O40: =IFERROR(SUMIFS(BASE!$L$7:$L$126,BASE!$G$7:$G$126,"OUTUBRO",BASE!$H$7:$H$126,$E40)/SUMIFS(BASE!$K$7:$K$126,BASE!$G$7:$G$126,"OUTUBRO",BASE!$H$7:$H$126,$E40),"") | P40: =IFERROR(SUMIFS(BASE!$L$7:$L$126,BASE!$G$7:$G$126,"NOVEMBRO",BASE!$H$7:$H$126,$E40)/SUMIFS(BASE!$K$7:$K$126,BASE!$G$7:$G$126,"NOVEMBRO",BASE!$H$7:$H$126,$E40),"") | Q40: =IFERROR(SUMIFS(BASE!$L$7:$L$126,BASE!$G$7:$G$126,"DEZEMBRO",BASE!$H$7:$H$126,$E40)/SUMIFS(BASE!$K$7:$K$126,BASE!$G$7:$G$126,"DEZEMBRO",BASE!$H$7:$H$126,$E40),"") | R40: =IFERROR(SUMIFS(BASE!$L$7:$L$126,BASE!$H$7:$H$126,$E40)/SUMIFS(BASE!$K$7:$K$126,BASE!$H$7:$H$126,$E40),"") -> 0.86640405
E41: RODRIGO SILVA - 997 | F41: =IFERROR(SUMIFS(BASE!$L$7:$L$126,BASE!$G$7:$G$126,"JANEIRO",BASE!$H$7:$H$126,$E41)/SUMIFS(BASE!$K$7:$K$126,BASE!$G$7:$G$126,"JANEIRO",BASE!$H$7:$H$126,$E41),"") -> 0.84425217 | G41: =IFERROR(SUMIFS(BASE!$L$7:$L$126,BASE!$G$7:$G$126,"FEVEREIRO",BASE!$H$7:$H$126,$E41)/SUMIFS(BASE!$K$7:$K$126,BASE!$G$7:$G$126,"FEVEREIRO",BASE!$H$7:$H$126,$E41),"") -> 0.61138724 | H41: =IFERROR(SUMIFS(BASE!$L$7:$L$126,BASE!$G$7:$G$126,"MARÇO",BASE!$H$7:$H$126,$E41)/SUMIFS(BASE!$K$7:$K$126,BASE!$G$7:$G$126,"MARÇO",BASE!$H$7:$H$126,$E41),"") -> 1.0709993 | I41: =IFERROR(SUMIFS(BASE!$L$7:$L$126,BASE!$G$7:$G$126,"ABRIL",BASE!$H$7:$H$126,$E41)/SUMIFS(BASE!$K$7:$K$126,BASE!$G$7:$G$126,"ABRIL",BASE!$H$7:$H$126,$E41),"") -> 0.9631192 | J41: =IFERROR(SUMIFS(BASE!$L$7:$L$126,BASE!$G$7:$G$126,"MAIO",BASE!$H$7:$H$126,$E41)/SUMIFS(BASE!$K$7:$K$126,BASE!$G$7:$G$126,"MAIO",BASE!$H$7:$H$126,$E41),"") -> 0.77418894 | K41: =IFERROR(SUMIFS(BASE!$L$7:$L$126,BASE!$G$7:$G$126,"JUNHO",BASE!$H$7:$H$126,$E41)/SUMIFS(BASE!$K$7:$K$126,BASE!$G$7:$G$126,"JUNHO",BASE!$H$7:$H$126,$E41),"") | L41: =IFERROR(SUMIFS(BASE!$L$7:$L$126,BASE!$G$7:$G$126,"JULHO",BASE!$H$7:$H$126,$E41)/SUMIFS(BASE!$K$7:$K$126,BASE!$G$7:$G$126,"JULHO",BASE!$H$7:$H$126,$E41),"") | M41: =IFERROR(SUMIFS(BASE!$L$7:$L$126,BASE!$G$7:$G$126,"AGOSTO",BASE!$H$7:$H$126,$E41)/SUMIFS(BASE!$K$7:$K$126,BASE!$G$7:$G$126,"AGOSTO",BASE!$H$7:$H$126,$E41),"") | N41: =IFERROR(SUMIFS(BASE!$L$7:$L$126,BASE!$G$7:$G$126,"SETEMBRO",BASE!$H$7:$H$126,$E41)/SUMIFS(BASE!$K$7:$K$126,BASE!$G$7:$G$126,"SETEMBRO",BASE!$H$7:$H$126,$E41),"") | O41: =IFERROR(SUMIFS(BASE!$L$7:$L$126,BASE!$G$7:$G$126,"OUTUBRO",BASE!$H$7:$H$126,$E41)/SUMIFS(BASE!$K$7:$K$126,BASE!$G$7:$G$126,"OUTUBRO",BASE!$H$7:$H$126,$E41),"") | P41: =IFERROR(SUMIFS(BASE!$L$7:$L$126,BASE!$G$7:$G$126,"NOVEMBRO",BASE!$H$7:$H$126,$E41)/SUMIFS(BASE!$K$7:$K$126,BASE!$G$7:$G$126,"NOVEMBRO",BASE!$H$7:$H$126,$E41),"") | Q41: =IFERROR(SUMIFS(BASE!$L$7:$L$126,BASE!$G$7:$G$126,"DEZEMBRO",BASE!$H$7:$H$126,$E41)/SUMIFS(BASE!$K$7:$K$126,BASE!$G$7:$G$126,"DEZEMBRO",BASE!$H$7:$H$126,$E41),"") | R41: =IFERROR(SUMIFS(BASE!$L$7:$L$126,BASE!$H$7:$H$126,$E41)/SUMIFS(BASE!$K$7:$K$126,BASE!$H$7:$H$126,$E41),"") -> 0.85305092
E42: RODO 3 - 1017 | F42: =IFERROR(SUMIFS(BASE!$L$7:$L$126,BASE!$G$7:$G$126,"JANEIRO",BASE!$H$7:$H$126,$E42)/SUMIFS(BASE!$K$7:$K$126,BASE!$G$7:$G$126,"JANEIRO",BASE!$H$7:$H$126,$E42),"") -> 1.0858681 | G42: =IFERROR(SUMIFS(BASE!$L$7:$L$126,BASE!$G$7:$G$126,"FEVEREIRO",BASE!$H$7:$H$126,$E42)/SUMIFS(BASE!$K$7:$K$126,BASE!$G$7:$G$126,"FEVEREIRO",BASE!$H$7:$H$126,$E42),"") -> 0.73609673 | H42: =IFERROR(SUMIFS(BASE!$L$7:$L$126,BASE!$G$7:$G$126,"MARÇO",BASE!$H$7:$H$126,$E42)/SUMIFS(BASE!$K$7:$K$126,BASE!$G$7:$G$126,"MARÇO",BASE!$H$7:$H$126,$E42),"") -> 1.2562848 | I42: =IFERROR(SUMIFS(BASE!$L$7:$L$126,BASE!$G$7:$G$126,"ABRIL",BASE!$H$7:$H$126,$E42)/SUMIFS(BASE!$K$7:$K$126,BASE!$G$7:$G$126,"ABRIL",BASE!$H$7:$H$126,$E42),"") -> 1.0369453 | J42: =IFERROR(SUMIFS(BASE!$L$7:$L$126,BASE!$G$7:$G$126,"MAIO",BASE!$H$7:$H$126,$E42)/SUMIFS(BASE!$K$7:$K$126,BASE!$G$7:$G$126,"MAIO",BASE!$H$7:$H$126,$E42),"") -> 0.63735294 | K42: =IFERROR(SUMIFS(BASE!$L$7:$L$126,BASE!$G$7:$G$126,"JUNHO",BASE!$H$7:$H$126,$E42)/SUMIFS(BASE!$K$7:$K$126,BASE!$G$7:$G$126,"JUNHO",BASE!$H$7:$H$126,$E42),"") | L42: =IFERROR(SUMIFS(BASE!$L$7:$L$126,BASE!$G$7:$G$126,"JULHO",BASE!$H$7:$H$126,$E42)/SUMIFS(BASE!$K$7:$K$126,BASE!$G$7:$G$126,"JULHO",BASE!$H$7:$H$126,$E42),"") | M42: =IFERROR(SUMIFS(BASE!$L$7:$L$126,BASE!$G$7:$G$126,"AGOSTO",BASE!$H$7:$H$126,$E42)/SUMIFS(BASE!$K$7:$K$126,BASE!$G$7:$G$126,"AGOSTO",BASE!$H$7:$H$126,$E42),"") | N42: =IFERROR(SUMIFS(BASE!$L$7:$L$126,BASE!$G$7:$G$126,"SETEMBRO",BASE!$H$7:$H$126,$E42)/SUMIFS(BASE!$K$7:$K$126,BASE!$G$7:$G$126,"SETEMBRO",BASE!$H$7:$H$126,$E42),"") | O42: =IFERROR(SUMIFS(BASE!$L$7:$L$126,BASE!$G$7:$G$126,"OUTUBRO",BASE!$H$7:$H$126,$E42)/SUMIFS(BASE!$K$7:$K$126,BASE!$G$7:$G$126,"OUTUBRO",BASE!$H$7:$H$126,$E42),"") | P42: =IFERROR(SUMIFS(BASE!$L$7:$L$126,BASE!$G$7:$G$126,"NOVEMBRO",BASE!$H$7:$H$126,$E42)/SUMIFS(BASE!$K$7:$K$126,BASE!$G$7:$G$126,"NOVEMBRO",BASE!$H$7:$H$126,$E42),"") | Q42: =IFERROR(SUMIFS(BASE!$L$7:$L$126,BASE!$G$7:$G$126,"DEZEMBRO",BASE!$H$7:$H$126,$E42)/SUMIFS(BASE!$K$7:$K$126,BASE!$G$7:$G$126,"DEZEMBRO",BASE!$H$7:$H$126,$E42),"") | R42: =IFERROR(SUMIFS(BASE!$L$7:$L$126,BASE!$H$7:$H$126,$E42)/SUMIFS(BASE!$K$7:$K$126,BASE!$H$7:$H$126,$E42),"") -> 0.91702455
E43: TOTAL
